2022-10-20 11:44:37,404 -  nornir.core -     INFO -        run() - Running task 'credentials_test' with args {} on 6 hosts
2022-10-20 11:45:40,243 -  nornir.core -     INFO -        run() - Running task 'credentials_test' with args {} on 6 hosts
2022-10-20 11:45:55,967 -  nornir.core -     INFO -        run() - Running task 'credentials_test' with args {} on 6 hosts
2022-10-20 11:51:41,216 -  nornir.core -     INFO -        run() - Running task 'credentials_test' with args {} on 6 hosts
2022-10-20 11:51:41,512 - nornir.core.task -    ERROR -      start() - Host 'cart-colo': task 'send_command' failed with traceback:
Traceback (most recent call last):
  File "/opt/Training/python/automation_training/venv/lib/python3.8/site-packages/nornir/core/task.py", line 99, in start
    r = self.task(self, **self.params)
  File "/opt/Training/python/automation_training/venv/lib/python3.8/site-packages/nornir_scrapli/tasks/core/send_command.py", line 36, in send_command
    scrapli_conn = task.host.get_connection("scrapli", task.nornir.config)
  File "/opt/Training/python/automation_training/venv/lib/python3.8/site-packages/nornir/core/inventory.py", line 494, in get_connection
    self.open_connection(
  File "/opt/Training/python/automation_training/venv/lib/python3.8/site-packages/nornir/core/inventory.py", line 546, in open_connection
    conn_obj.open(
  File "/opt/Training/python/automation_training/venv/lib/python3.8/site-packages/nornir_scrapli/connection.py", line 105, in open
    connection.open()
  File "/opt/Training/python/automation_training/venv/lib/python3.8/site-packages/scrapli/driver/base/sync_driver.py", line 88, in open
    self.channel.channel_authenticate_ssh(
  File "/opt/Training/python/automation_training/venv/lib/python3.8/site-packages/scrapli/decorators.py", line 216, in decorate
    return _multiprocessing_timeout(
  File "/opt/Training/python/automation_training/venv/lib/python3.8/site-packages/scrapli/decorators.py", line 113, in _multiprocessing_timeout
    return future.result()
  File "/usr/lib/python3.8/concurrent/futures/_base.py", line 437, in result
    return self.__get_result()
  File "/usr/lib/python3.8/concurrent/futures/_base.py", line 389, in __get_result
    raise self._exception
  File "/usr/lib/python3.8/concurrent/futures/thread.py", line 57, in run
    result = self.fn(*self.args, **self.kwargs)
  File "/opt/Training/python/automation_training/venv/lib/python3.8/site-packages/scrapli/channel/sync_channel.py", line 290, in channel_authenticate_ssh
    self._ssh_message_handler(output=authenticate_buf)
  File "/opt/Training/python/automation_training/venv/lib/python3.8/site-packages/scrapli/channel/base_channel.py", line 432, in _ssh_message_handler
    raise ScrapliAuthenticationFailed(msg)
scrapli.exceptions.ScrapliAuthenticationFailed: b'\npermission denied, please try again.\n'

2022-10-20 11:51:41,512 - nornir.core.task -    ERROR -      start() - Host 'cart-colo': task 'credentials_test' failed with traceback:
Traceback (most recent call last):
  File "/opt/Training/python/automation_training/venv/lib/python3.8/site-packages/nornir/core/task.py", line 99, in start
    r = self.task(self, **self.params)
  File "script1.py", line 8, in credentials_test
    task.run(send_command, command="show ip int br")
  File "/opt/Training/python/automation_training/venv/lib/python3.8/site-packages/nornir/core/task.py", line 174, in run
    raise NornirSubTaskError(task=run_task, result=r)
nornir.core.exceptions.NornirSubTaskError: Subtask: send_command (failed)


2022-10-20 11:51:41,598 - nornir.core.task -    ERROR -      start() - Host 'ny5-feed-sw1a': task 'send_command' failed with traceback:
Traceback (most recent call last):
  File "/opt/Training/python/automation_training/venv/lib/python3.8/site-packages/nornir/core/task.py", line 99, in start
    r = self.task(self, **self.params)
  File "/opt/Training/python/automation_training/venv/lib/python3.8/site-packages/nornir_scrapli/tasks/core/send_command.py", line 36, in send_command
    scrapli_conn = task.host.get_connection("scrapli", task.nornir.config)
  File "/opt/Training/python/automation_training/venv/lib/python3.8/site-packages/nornir/core/inventory.py", line 494, in get_connection
    self.open_connection(
  File "/opt/Training/python/automation_training/venv/lib/python3.8/site-packages/nornir/core/inventory.py", line 546, in open_connection
    conn_obj.open(
  File "/opt/Training/python/automation_training/venv/lib/python3.8/site-packages/nornir_scrapli/connection.py", line 105, in open
    connection.open()
  File "/opt/Training/python/automation_training/venv/lib/python3.8/site-packages/scrapli/driver/base/sync_driver.py", line 88, in open
    self.channel.channel_authenticate_ssh(
  File "/opt/Training/python/automation_training/venv/lib/python3.8/site-packages/scrapli/decorators.py", line 216, in decorate
    return _multiprocessing_timeout(
  File "/opt/Training/python/automation_training/venv/lib/python3.8/site-packages/scrapli/decorators.py", line 113, in _multiprocessing_timeout
    return future.result()
  File "/usr/lib/python3.8/concurrent/futures/_base.py", line 437, in result
    return self.__get_result()
  File "/usr/lib/python3.8/concurrent/futures/_base.py", line 389, in __get_result
    raise self._exception
  File "/usr/lib/python3.8/concurrent/futures/thread.py", line 57, in run
    result = self.fn(*self.args, **self.kwargs)
  File "/opt/Training/python/automation_training/venv/lib/python3.8/site-packages/scrapli/channel/sync_channel.py", line 302, in channel_authenticate_ssh
    raise ScrapliAuthenticationFailed(msg)
scrapli.exceptions.ScrapliAuthenticationFailed: password prompt seen more than once, assuming auth failed

2022-10-20 11:51:41,598 - nornir.core.task -    ERROR -      start() - Host 'ny5-feed-sw1a': task 'credentials_test' failed with traceback:
Traceback (most recent call last):
  File "/opt/Training/python/automation_training/venv/lib/python3.8/site-packages/nornir/core/task.py", line 99, in start
    r = self.task(self, **self.params)
  File "script1.py", line 8, in credentials_test
    task.run(send_command, command="show ip int br")
  File "/opt/Training/python/automation_training/venv/lib/python3.8/site-packages/nornir/core/task.py", line 174, in run
    raise NornirSubTaskError(task=run_task, result=r)
nornir.core.exceptions.NornirSubTaskError: Subtask: send_command (failed)


2022-10-20 11:51:41,613 - nornir.core.task -    ERROR -      start() - Host 'ny5-feed-sw2': task 'send_command' failed with traceback:
Traceback (most recent call last):
  File "/opt/Training/python/automation_training/venv/lib/python3.8/site-packages/nornir/core/task.py", line 99, in start
    r = self.task(self, **self.params)
  File "/opt/Training/python/automation_training/venv/lib/python3.8/site-packages/nornir_scrapli/tasks/core/send_command.py", line 36, in send_command
    scrapli_conn = task.host.get_connection("scrapli", task.nornir.config)
  File "/opt/Training/python/automation_training/venv/lib/python3.8/site-packages/nornir/core/inventory.py", line 494, in get_connection
    self.open_connection(
  File "/opt/Training/python/automation_training/venv/lib/python3.8/site-packages/nornir/core/inventory.py", line 546, in open_connection
    conn_obj.open(
  File "/opt/Training/python/automation_training/venv/lib/python3.8/site-packages/nornir_scrapli/connection.py", line 105, in open
    connection.open()
  File "/opt/Training/python/automation_training/venv/lib/python3.8/site-packages/scrapli/driver/base/sync_driver.py", line 88, in open
    self.channel.channel_authenticate_ssh(
  File "/opt/Training/python/automation_training/venv/lib/python3.8/site-packages/scrapli/decorators.py", line 216, in decorate
    return _multiprocessing_timeout(
  File "/opt/Training/python/automation_training/venv/lib/python3.8/site-packages/scrapli/decorators.py", line 113, in _multiprocessing_timeout
    return future.result()
  File "/usr/lib/python3.8/concurrent/futures/_base.py", line 437, in result
    return self.__get_result()
  File "/usr/lib/python3.8/concurrent/futures/_base.py", line 389, in __get_result
    raise self._exception
  File "/usr/lib/python3.8/concurrent/futures/thread.py", line 57, in run
    result = self.fn(*self.args, **self.kwargs)
  File "/opt/Training/python/automation_training/venv/lib/python3.8/site-packages/scrapli/channel/sync_channel.py", line 302, in channel_authenticate_ssh
    raise ScrapliAuthenticationFailed(msg)
scrapli.exceptions.ScrapliAuthenticationFailed: password prompt seen more than once, assuming auth failed

2022-10-20 11:51:41,613 - nornir.core.task -    ERROR -      start() - Host 'ny5-feed-sw2': task 'credentials_test' failed with traceback:
Traceback (most recent call last):
  File "/opt/Training/python/automation_training/venv/lib/python3.8/site-packages/nornir/core/task.py", line 99, in start
    r = self.task(self, **self.params)
  File "script1.py", line 8, in credentials_test
    task.run(send_command, command="show ip int br")
  File "/opt/Training/python/automation_training/venv/lib/python3.8/site-packages/nornir/core/task.py", line 174, in run
    raise NornirSubTaskError(task=run_task, result=r)
nornir.core.exceptions.NornirSubTaskError: Subtask: send_command (failed)


2022-10-20 11:51:41,616 - nornir.core.task -    ERROR -      start() - Host 'ny5-feed-sw3': task 'send_command' failed with traceback:
Traceback (most recent call last):
  File "/opt/Training/python/automation_training/venv/lib/python3.8/site-packages/nornir/core/task.py", line 99, in start
    r = self.task(self, **self.params)
  File "/opt/Training/python/automation_training/venv/lib/python3.8/site-packages/nornir_scrapli/tasks/core/send_command.py", line 36, in send_command
    scrapli_conn = task.host.get_connection("scrapli", task.nornir.config)
  File "/opt/Training/python/automation_training/venv/lib/python3.8/site-packages/nornir/core/inventory.py", line 494, in get_connection
    self.open_connection(
  File "/opt/Training/python/automation_training/venv/lib/python3.8/site-packages/nornir/core/inventory.py", line 546, in open_connection
    conn_obj.open(
  File "/opt/Training/python/automation_training/venv/lib/python3.8/site-packages/nornir_scrapli/connection.py", line 105, in open
    connection.open()
  File "/opt/Training/python/automation_training/venv/lib/python3.8/site-packages/scrapli/driver/base/sync_driver.py", line 88, in open
    self.channel.channel_authenticate_ssh(
  File "/opt/Training/python/automation_training/venv/lib/python3.8/site-packages/scrapli/decorators.py", line 216, in decorate
    return _multiprocessing_timeout(
  File "/opt/Training/python/automation_training/venv/lib/python3.8/site-packages/scrapli/decorators.py", line 113, in _multiprocessing_timeout
    return future.result()
  File "/usr/lib/python3.8/concurrent/futures/_base.py", line 437, in result
    return self.__get_result()
  File "/usr/lib/python3.8/concurrent/futures/_base.py", line 389, in __get_result
    raise self._exception
  File "/usr/lib/python3.8/concurrent/futures/thread.py", line 57, in run
    result = self.fn(*self.args, **self.kwargs)
  File "/opt/Training/python/automation_training/venv/lib/python3.8/site-packages/scrapli/channel/sync_channel.py", line 302, in channel_authenticate_ssh
    raise ScrapliAuthenticationFailed(msg)
scrapli.exceptions.ScrapliAuthenticationFailed: password prompt seen more than once, assuming auth failed

2022-10-20 11:51:41,616 - nornir.core.task -    ERROR -      start() - Host 'ny5-feed-sw3': task 'credentials_test' failed with traceback:
Traceback (most recent call last):
  File "/opt/Training/python/automation_training/venv/lib/python3.8/site-packages/nornir/core/task.py", line 99, in start
    r = self.task(self, **self.params)
  File "script1.py", line 8, in credentials_test
    task.run(send_command, command="show ip int br")
  File "/opt/Training/python/automation_training/venv/lib/python3.8/site-packages/nornir/core/task.py", line 174, in run
    raise NornirSubTaskError(task=run_task, result=r)
nornir.core.exceptions.NornirSubTaskError: Subtask: send_command (failed)


2022-10-20 11:51:41,696 - nornir.core.task -    ERROR -      start() - Host 'ny5-feed-sw1b': task 'send_command' failed with traceback:
Traceback (most recent call last):
  File "/opt/Training/python/automation_training/venv/lib/python3.8/site-packages/nornir/core/task.py", line 99, in start
    r = self.task(self, **self.params)
  File "/opt/Training/python/automation_training/venv/lib/python3.8/site-packages/nornir_scrapli/tasks/core/send_command.py", line 36, in send_command
    scrapli_conn = task.host.get_connection("scrapli", task.nornir.config)
  File "/opt/Training/python/automation_training/venv/lib/python3.8/site-packages/nornir/core/inventory.py", line 494, in get_connection
    self.open_connection(
  File "/opt/Training/python/automation_training/venv/lib/python3.8/site-packages/nornir/core/inventory.py", line 546, in open_connection
    conn_obj.open(
  File "/opt/Training/python/automation_training/venv/lib/python3.8/site-packages/nornir_scrapli/connection.py", line 105, in open
    connection.open()
  File "/opt/Training/python/automation_training/venv/lib/python3.8/site-packages/scrapli/driver/base/sync_driver.py", line 88, in open
    self.channel.channel_authenticate_ssh(
  File "/opt/Training/python/automation_training/venv/lib/python3.8/site-packages/scrapli/decorators.py", line 216, in decorate
    return _multiprocessing_timeout(
  File "/opt/Training/python/automation_training/venv/lib/python3.8/site-packages/scrapli/decorators.py", line 113, in _multiprocessing_timeout
    return future.result()
  File "/usr/lib/python3.8/concurrent/futures/_base.py", line 437, in result
    return self.__get_result()
  File "/usr/lib/python3.8/concurrent/futures/_base.py", line 389, in __get_result
    raise self._exception
  File "/usr/lib/python3.8/concurrent/futures/thread.py", line 57, in run
    result = self.fn(*self.args, **self.kwargs)
  File "/opt/Training/python/automation_training/venv/lib/python3.8/site-packages/scrapli/channel/sync_channel.py", line 302, in channel_authenticate_ssh
    raise ScrapliAuthenticationFailed(msg)
scrapli.exceptions.ScrapliAuthenticationFailed: password prompt seen more than once, assuming auth failed

2022-10-20 11:51:41,696 - nornir.core.task -    ERROR -      start() - Host 'ny5-feed-sw1b': task 'credentials_test' failed with traceback:
Traceback (most recent call last):
  File "/opt/Training/python/automation_training/venv/lib/python3.8/site-packages/nornir/core/task.py", line 99, in start
    r = self.task(self, **self.params)
  File "script1.py", line 8, in credentials_test
    task.run(send_command, command="show ip int br")
  File "/opt/Training/python/automation_training/venv/lib/python3.8/site-packages/nornir/core/task.py", line 174, in run
    raise NornirSubTaskError(task=run_task, result=r)
nornir.core.exceptions.NornirSubTaskError: Subtask: send_command (failed)


2022-10-20 11:51:41,732 - nornir.core.task -    ERROR -      start() - Host 'telx-colo': task 'send_command' failed with traceback:
Traceback (most recent call last):
  File "/opt/Training/python/automation_training/venv/lib/python3.8/site-packages/nornir/core/task.py", line 99, in start
    r = self.task(self, **self.params)
  File "/opt/Training/python/automation_training/venv/lib/python3.8/site-packages/nornir_scrapli/tasks/core/send_command.py", line 36, in send_command
    scrapli_conn = task.host.get_connection("scrapli", task.nornir.config)
  File "/opt/Training/python/automation_training/venv/lib/python3.8/site-packages/nornir/core/inventory.py", line 494, in get_connection
    self.open_connection(
  File "/opt/Training/python/automation_training/venv/lib/python3.8/site-packages/nornir/core/inventory.py", line 546, in open_connection
    conn_obj.open(
  File "/opt/Training/python/automation_training/venv/lib/python3.8/site-packages/nornir_scrapli/connection.py", line 105, in open
    connection.open()
  File "/opt/Training/python/automation_training/venv/lib/python3.8/site-packages/scrapli/driver/base/sync_driver.py", line 88, in open
    self.channel.channel_authenticate_ssh(
  File "/opt/Training/python/automation_training/venv/lib/python3.8/site-packages/scrapli/decorators.py", line 216, in decorate
    return _multiprocessing_timeout(
  File "/opt/Training/python/automation_training/venv/lib/python3.8/site-packages/scrapli/decorators.py", line 113, in _multiprocessing_timeout
    return future.result()
  File "/usr/lib/python3.8/concurrent/futures/_base.py", line 437, in result
    return self.__get_result()
  File "/usr/lib/python3.8/concurrent/futures/_base.py", line 389, in __get_result
    raise self._exception
  File "/usr/lib/python3.8/concurrent/futures/thread.py", line 57, in run
    result = self.fn(*self.args, **self.kwargs)
  File "/opt/Training/python/automation_training/venv/lib/python3.8/site-packages/scrapli/channel/sync_channel.py", line 302, in channel_authenticate_ssh
    raise ScrapliAuthenticationFailed(msg)
scrapli.exceptions.ScrapliAuthenticationFailed: password prompt seen more than once, assuming auth failed

2022-10-20 11:51:41,732 - nornir.core.task -    ERROR -      start() - Host 'telx-colo': task 'credentials_test' failed with traceback:
Traceback (most recent call last):
  File "/opt/Training/python/automation_training/venv/lib/python3.8/site-packages/nornir/core/task.py", line 99, in start
    r = self.task(self, **self.params)
  File "script1.py", line 8, in credentials_test
    task.run(send_command, command="show ip int br")
  File "/opt/Training/python/automation_training/venv/lib/python3.8/site-packages/nornir/core/task.py", line 174, in run
    raise NornirSubTaskError(task=run_task, result=r)
nornir.core.exceptions.NornirSubTaskError: Subtask: send_command (failed)


2022-10-20 11:54:05,558 -  nornir.core -     INFO -        run() - Running task 'credentials_test' with args {} on 6 hosts
2022-10-20 11:54:05,870 - nornir.core.task -    ERROR -      start() - Host 'cart-colo': task 'send_command' failed with traceback:
Traceback (most recent call last):
  File "/opt/Training/python/automation_training/venv/lib/python3.8/site-packages/nornir/core/task.py", line 99, in start
    r = self.task(self, **self.params)
  File "/opt/Training/python/automation_training/venv/lib/python3.8/site-packages/nornir_scrapli/tasks/core/send_command.py", line 36, in send_command
    scrapli_conn = task.host.get_connection("scrapli", task.nornir.config)
  File "/opt/Training/python/automation_training/venv/lib/python3.8/site-packages/nornir/core/inventory.py", line 494, in get_connection
    self.open_connection(
  File "/opt/Training/python/automation_training/venv/lib/python3.8/site-packages/nornir/core/inventory.py", line 546, in open_connection
    conn_obj.open(
  File "/opt/Training/python/automation_training/venv/lib/python3.8/site-packages/nornir_scrapli/connection.py", line 105, in open
    connection.open()
  File "/opt/Training/python/automation_training/venv/lib/python3.8/site-packages/scrapli/driver/base/sync_driver.py", line 88, in open
    self.channel.channel_authenticate_ssh(
  File "/opt/Training/python/automation_training/venv/lib/python3.8/site-packages/scrapli/decorators.py", line 216, in decorate
    return _multiprocessing_timeout(
  File "/opt/Training/python/automation_training/venv/lib/python3.8/site-packages/scrapli/decorators.py", line 113, in _multiprocessing_timeout
    return future.result()
  File "/usr/lib/python3.8/concurrent/futures/_base.py", line 437, in result
    return self.__get_result()
  File "/usr/lib/python3.8/concurrent/futures/_base.py", line 389, in __get_result
    raise self._exception
  File "/usr/lib/python3.8/concurrent/futures/thread.py", line 57, in run
    result = self.fn(*self.args, **self.kwargs)
  File "/opt/Training/python/automation_training/venv/lib/python3.8/site-packages/scrapli/channel/sync_channel.py", line 290, in channel_authenticate_ssh
    self._ssh_message_handler(output=authenticate_buf)
  File "/opt/Training/python/automation_training/venv/lib/python3.8/site-packages/scrapli/channel/base_channel.py", line 432, in _ssh_message_handler
    raise ScrapliAuthenticationFailed(msg)
scrapli.exceptions.ScrapliAuthenticationFailed: b"\npermission denied, please try again.\ndoug@192.168.86.200's password: "

2022-10-20 11:54:05,870 - nornir.core.task -    ERROR -      start() - Host 'cart-colo': task 'credentials_test' failed with traceback:
Traceback (most recent call last):
  File "/opt/Training/python/automation_training/venv/lib/python3.8/site-packages/nornir/core/task.py", line 99, in start
    r = self.task(self, **self.params)
  File "script1.py", line 10, in credentials_test
    task.run(send_command, command="show ip int br")
  File "/opt/Training/python/automation_training/venv/lib/python3.8/site-packages/nornir/core/task.py", line 174, in run
    raise NornirSubTaskError(task=run_task, result=r)
nornir.core.exceptions.NornirSubTaskError: Subtask: send_command (failed)


2022-10-20 11:54:05,940 - nornir.core.task -    ERROR -      start() - Host 'ny5-feed-sw1a': task 'send_command' failed with traceback:
Traceback (most recent call last):
  File "/opt/Training/python/automation_training/venv/lib/python3.8/site-packages/nornir/core/task.py", line 99, in start
    r = self.task(self, **self.params)
  File "/opt/Training/python/automation_training/venv/lib/python3.8/site-packages/nornir_scrapli/tasks/core/send_command.py", line 36, in send_command
    scrapli_conn = task.host.get_connection("scrapli", task.nornir.config)
  File "/opt/Training/python/automation_training/venv/lib/python3.8/site-packages/nornir/core/inventory.py", line 494, in get_connection
    self.open_connection(
  File "/opt/Training/python/automation_training/venv/lib/python3.8/site-packages/nornir/core/inventory.py", line 546, in open_connection
    conn_obj.open(
  File "/opt/Training/python/automation_training/venv/lib/python3.8/site-packages/nornir_scrapli/connection.py", line 105, in open
    connection.open()
  File "/opt/Training/python/automation_training/venv/lib/python3.8/site-packages/scrapli/driver/base/sync_driver.py", line 88, in open
    self.channel.channel_authenticate_ssh(
  File "/opt/Training/python/automation_training/venv/lib/python3.8/site-packages/scrapli/decorators.py", line 216, in decorate
    return _multiprocessing_timeout(
  File "/opt/Training/python/automation_training/venv/lib/python3.8/site-packages/scrapli/decorators.py", line 113, in _multiprocessing_timeout
    return future.result()
  File "/usr/lib/python3.8/concurrent/futures/_base.py", line 437, in result
    return self.__get_result()
  File "/usr/lib/python3.8/concurrent/futures/_base.py", line 389, in __get_result
    raise self._exception
  File "/usr/lib/python3.8/concurrent/futures/thread.py", line 57, in run
    result = self.fn(*self.args, **self.kwargs)
  File "/opt/Training/python/automation_training/venv/lib/python3.8/site-packages/scrapli/channel/sync_channel.py", line 302, in channel_authenticate_ssh
    raise ScrapliAuthenticationFailed(msg)
scrapli.exceptions.ScrapliAuthenticationFailed: password prompt seen more than once, assuming auth failed

2022-10-20 11:54:05,940 - nornir.core.task -    ERROR -      start() - Host 'ny5-feed-sw1a': task 'credentials_test' failed with traceback:
Traceback (most recent call last):
  File "/opt/Training/python/automation_training/venv/lib/python3.8/site-packages/nornir/core/task.py", line 99, in start
    r = self.task(self, **self.params)
  File "script1.py", line 10, in credentials_test
    task.run(send_command, command="show ip int br")
  File "/opt/Training/python/automation_training/venv/lib/python3.8/site-packages/nornir/core/task.py", line 174, in run
    raise NornirSubTaskError(task=run_task, result=r)
nornir.core.exceptions.NornirSubTaskError: Subtask: send_command (failed)


2022-10-20 11:54:05,942 - nornir.core.task -    ERROR -      start() - Host 'ny5-feed-sw3': task 'send_command' failed with traceback:
Traceback (most recent call last):
  File "/opt/Training/python/automation_training/venv/lib/python3.8/site-packages/nornir/core/task.py", line 99, in start
    r = self.task(self, **self.params)
  File "/opt/Training/python/automation_training/venv/lib/python3.8/site-packages/nornir_scrapli/tasks/core/send_command.py", line 36, in send_command
    scrapli_conn = task.host.get_connection("scrapli", task.nornir.config)
  File "/opt/Training/python/automation_training/venv/lib/python3.8/site-packages/nornir/core/inventory.py", line 494, in get_connection
    self.open_connection(
  File "/opt/Training/python/automation_training/venv/lib/python3.8/site-packages/nornir/core/inventory.py", line 546, in open_connection
    conn_obj.open(
  File "/opt/Training/python/automation_training/venv/lib/python3.8/site-packages/nornir_scrapli/connection.py", line 105, in open
    connection.open()
  File "/opt/Training/python/automation_training/venv/lib/python3.8/site-packages/scrapli/driver/base/sync_driver.py", line 88, in open
    self.channel.channel_authenticate_ssh(
  File "/opt/Training/python/automation_training/venv/lib/python3.8/site-packages/scrapli/decorators.py", line 216, in decorate
    return _multiprocessing_timeout(
  File "/opt/Training/python/automation_training/venv/lib/python3.8/site-packages/scrapli/decorators.py", line 113, in _multiprocessing_timeout
    return future.result()
  File "/usr/lib/python3.8/concurrent/futures/_base.py", line 437, in result
    return self.__get_result()
  File "/usr/lib/python3.8/concurrent/futures/_base.py", line 389, in __get_result
    raise self._exception
  File "/usr/lib/python3.8/concurrent/futures/thread.py", line 57, in run
    result = self.fn(*self.args, **self.kwargs)
  File "/opt/Training/python/automation_training/venv/lib/python3.8/site-packages/scrapli/channel/sync_channel.py", line 302, in channel_authenticate_ssh
    raise ScrapliAuthenticationFailed(msg)
scrapli.exceptions.ScrapliAuthenticationFailed: password prompt seen more than once, assuming auth failed

2022-10-20 11:54:05,942 - nornir.core.task -    ERROR -      start() - Host 'ny5-feed-sw3': task 'credentials_test' failed with traceback:
Traceback (most recent call last):
  File "/opt/Training/python/automation_training/venv/lib/python3.8/site-packages/nornir/core/task.py", line 99, in start
    r = self.task(self, **self.params)
  File "script1.py", line 10, in credentials_test
    task.run(send_command, command="show ip int br")
  File "/opt/Training/python/automation_training/venv/lib/python3.8/site-packages/nornir/core/task.py", line 174, in run
    raise NornirSubTaskError(task=run_task, result=r)
nornir.core.exceptions.NornirSubTaskError: Subtask: send_command (failed)


2022-10-20 11:54:05,958 - nornir.core.task -    ERROR -      start() - Host 'telx-colo': task 'send_command' failed with traceback:
Traceback (most recent call last):
  File "/opt/Training/python/automation_training/venv/lib/python3.8/site-packages/nornir/core/task.py", line 99, in start
    r = self.task(self, **self.params)
  File "/opt/Training/python/automation_training/venv/lib/python3.8/site-packages/nornir_scrapli/tasks/core/send_command.py", line 36, in send_command
    scrapli_conn = task.host.get_connection("scrapli", task.nornir.config)
  File "/opt/Training/python/automation_training/venv/lib/python3.8/site-packages/nornir/core/inventory.py", line 494, in get_connection
    self.open_connection(
  File "/opt/Training/python/automation_training/venv/lib/python3.8/site-packages/nornir/core/inventory.py", line 546, in open_connection
    conn_obj.open(
  File "/opt/Training/python/automation_training/venv/lib/python3.8/site-packages/nornir_scrapli/connection.py", line 105, in open
    connection.open()
  File "/opt/Training/python/automation_training/venv/lib/python3.8/site-packages/scrapli/driver/base/sync_driver.py", line 88, in open
    self.channel.channel_authenticate_ssh(
  File "/opt/Training/python/automation_training/venv/lib/python3.8/site-packages/scrapli/decorators.py", line 216, in decorate
    return _multiprocessing_timeout(
  File "/opt/Training/python/automation_training/venv/lib/python3.8/site-packages/scrapli/decorators.py", line 113, in _multiprocessing_timeout
    return future.result()
  File "/usr/lib/python3.8/concurrent/futures/_base.py", line 437, in result
    return self.__get_result()
  File "/usr/lib/python3.8/concurrent/futures/_base.py", line 389, in __get_result
    raise self._exception
  File "/usr/lib/python3.8/concurrent/futures/thread.py", line 57, in run
    result = self.fn(*self.args, **self.kwargs)
  File "/opt/Training/python/automation_training/venv/lib/python3.8/site-packages/scrapli/channel/sync_channel.py", line 302, in channel_authenticate_ssh
    raise ScrapliAuthenticationFailed(msg)
scrapli.exceptions.ScrapliAuthenticationFailed: password prompt seen more than once, assuming auth failed

2022-10-20 11:54:05,958 - nornir.core.task -    ERROR -      start() - Host 'telx-colo': task 'credentials_test' failed with traceback:
Traceback (most recent call last):
  File "/opt/Training/python/automation_training/venv/lib/python3.8/site-packages/nornir/core/task.py", line 99, in start
    r = self.task(self, **self.params)
  File "script1.py", line 10, in credentials_test
    task.run(send_command, command="show ip int br")
  File "/opt/Training/python/automation_training/venv/lib/python3.8/site-packages/nornir/core/task.py", line 174, in run
    raise NornirSubTaskError(task=run_task, result=r)
nornir.core.exceptions.NornirSubTaskError: Subtask: send_command (failed)


2022-10-20 11:54:05,968 - nornir.core.task -    ERROR -      start() - Host 'ny5-feed-sw1b': task 'send_command' failed with traceback:
Traceback (most recent call last):
  File "/opt/Training/python/automation_training/venv/lib/python3.8/site-packages/nornir/core/task.py", line 99, in start
    r = self.task(self, **self.params)
  File "/opt/Training/python/automation_training/venv/lib/python3.8/site-packages/nornir_scrapli/tasks/core/send_command.py", line 36, in send_command
    scrapli_conn = task.host.get_connection("scrapli", task.nornir.config)
  File "/opt/Training/python/automation_training/venv/lib/python3.8/site-packages/nornir/core/inventory.py", line 494, in get_connection
    self.open_connection(
  File "/opt/Training/python/automation_training/venv/lib/python3.8/site-packages/nornir/core/inventory.py", line 546, in open_connection
    conn_obj.open(
  File "/opt/Training/python/automation_training/venv/lib/python3.8/site-packages/nornir_scrapli/connection.py", line 105, in open
    connection.open()
  File "/opt/Training/python/automation_training/venv/lib/python3.8/site-packages/scrapli/driver/base/sync_driver.py", line 88, in open
    self.channel.channel_authenticate_ssh(
  File "/opt/Training/python/automation_training/venv/lib/python3.8/site-packages/scrapli/decorators.py", line 216, in decorate
    return _multiprocessing_timeout(
  File "/opt/Training/python/automation_training/venv/lib/python3.8/site-packages/scrapli/decorators.py", line 113, in _multiprocessing_timeout
    return future.result()
  File "/usr/lib/python3.8/concurrent/futures/_base.py", line 437, in result
    return self.__get_result()
  File "/usr/lib/python3.8/concurrent/futures/_base.py", line 389, in __get_result
    raise self._exception
  File "/usr/lib/python3.8/concurrent/futures/thread.py", line 57, in run
    result = self.fn(*self.args, **self.kwargs)
  File "/opt/Training/python/automation_training/venv/lib/python3.8/site-packages/scrapli/channel/sync_channel.py", line 302, in channel_authenticate_ssh
    raise ScrapliAuthenticationFailed(msg)
scrapli.exceptions.ScrapliAuthenticationFailed: password prompt seen more than once, assuming auth failed

2022-10-20 11:54:05,969 - nornir.core.task -    ERROR -      start() - Host 'ny5-feed-sw1b': task 'credentials_test' failed with traceback:
Traceback (most recent call last):
  File "/opt/Training/python/automation_training/venv/lib/python3.8/site-packages/nornir/core/task.py", line 99, in start
    r = self.task(self, **self.params)
  File "script1.py", line 10, in credentials_test
    task.run(send_command, command="show ip int br")
  File "/opt/Training/python/automation_training/venv/lib/python3.8/site-packages/nornir/core/task.py", line 174, in run
    raise NornirSubTaskError(task=run_task, result=r)
nornir.core.exceptions.NornirSubTaskError: Subtask: send_command (failed)


2022-10-20 11:54:05,969 - nornir.core.task -    ERROR -      start() - Host 'ny5-feed-sw2': task 'send_command' failed with traceback:
Traceback (most recent call last):
  File "/opt/Training/python/automation_training/venv/lib/python3.8/site-packages/nornir/core/task.py", line 99, in start
    r = self.task(self, **self.params)
  File "/opt/Training/python/automation_training/venv/lib/python3.8/site-packages/nornir_scrapli/tasks/core/send_command.py", line 36, in send_command
    scrapli_conn = task.host.get_connection("scrapli", task.nornir.config)
  File "/opt/Training/python/automation_training/venv/lib/python3.8/site-packages/nornir/core/inventory.py", line 494, in get_connection
    self.open_connection(
  File "/opt/Training/python/automation_training/venv/lib/python3.8/site-packages/nornir/core/inventory.py", line 546, in open_connection
    conn_obj.open(
  File "/opt/Training/python/automation_training/venv/lib/python3.8/site-packages/nornir_scrapli/connection.py", line 105, in open
    connection.open()
  File "/opt/Training/python/automation_training/venv/lib/python3.8/site-packages/scrapli/driver/base/sync_driver.py", line 88, in open
    self.channel.channel_authenticate_ssh(
  File "/opt/Training/python/automation_training/venv/lib/python3.8/site-packages/scrapli/decorators.py", line 216, in decorate
    return _multiprocessing_timeout(
  File "/opt/Training/python/automation_training/venv/lib/python3.8/site-packages/scrapli/decorators.py", line 113, in _multiprocessing_timeout
    return future.result()
  File "/usr/lib/python3.8/concurrent/futures/_base.py", line 437, in result
    return self.__get_result()
  File "/usr/lib/python3.8/concurrent/futures/_base.py", line 389, in __get_result
    raise self._exception
  File "/usr/lib/python3.8/concurrent/futures/thread.py", line 57, in run
    result = self.fn(*self.args, **self.kwargs)
  File "/opt/Training/python/automation_training/venv/lib/python3.8/site-packages/scrapli/channel/sync_channel.py", line 302, in channel_authenticate_ssh
    raise ScrapliAuthenticationFailed(msg)
scrapli.exceptions.ScrapliAuthenticationFailed: password prompt seen more than once, assuming auth failed

2022-10-20 11:54:05,969 - nornir.core.task -    ERROR -      start() - Host 'ny5-feed-sw2': task 'credentials_test' failed with traceback:
Traceback (most recent call last):
  File "/opt/Training/python/automation_training/venv/lib/python3.8/site-packages/nornir/core/task.py", line 99, in start
    r = self.task(self, **self.params)
  File "script1.py", line 10, in credentials_test
    task.run(send_command, command="show ip int br")
  File "/opt/Training/python/automation_training/venv/lib/python3.8/site-packages/nornir/core/task.py", line 174, in run
    raise NornirSubTaskError(task=run_task, result=r)
nornir.core.exceptions.NornirSubTaskError: Subtask: send_command (failed)


2022-10-20 11:54:57,526 -  nornir.core -     INFO -        run() - Running task 'credentials_test' with args {} on 6 hosts
2022-10-20 11:54:57,880 - nornir.core.task -    ERROR -      start() - Host 'cart-colo': task 'send_command' failed with traceback:
Traceback (most recent call last):
  File "/opt/Training/python/automation_training/venv/lib/python3.8/site-packages/nornir/core/task.py", line 99, in start
    r = self.task(self, **self.params)
  File "/opt/Training/python/automation_training/venv/lib/python3.8/site-packages/nornir_scrapli/tasks/core/send_command.py", line 36, in send_command
    scrapli_conn = task.host.get_connection("scrapli", task.nornir.config)
  File "/opt/Training/python/automation_training/venv/lib/python3.8/site-packages/nornir/core/inventory.py", line 494, in get_connection
    self.open_connection(
  File "/opt/Training/python/automation_training/venv/lib/python3.8/site-packages/nornir/core/inventory.py", line 546, in open_connection
    conn_obj.open(
  File "/opt/Training/python/automation_training/venv/lib/python3.8/site-packages/nornir_scrapli/connection.py", line 105, in open
    connection.open()
  File "/opt/Training/python/automation_training/venv/lib/python3.8/site-packages/scrapli/driver/base/sync_driver.py", line 88, in open
    self.channel.channel_authenticate_ssh(
  File "/opt/Training/python/automation_training/venv/lib/python3.8/site-packages/scrapli/decorators.py", line 216, in decorate
    return _multiprocessing_timeout(
  File "/opt/Training/python/automation_training/venv/lib/python3.8/site-packages/scrapli/decorators.py", line 113, in _multiprocessing_timeout
    return future.result()
  File "/usr/lib/python3.8/concurrent/futures/_base.py", line 437, in result
    return self.__get_result()
  File "/usr/lib/python3.8/concurrent/futures/_base.py", line 389, in __get_result
    raise self._exception
  File "/usr/lib/python3.8/concurrent/futures/thread.py", line 57, in run
    result = self.fn(*self.args, **self.kwargs)
  File "/opt/Training/python/automation_training/venv/lib/python3.8/site-packages/scrapli/channel/sync_channel.py", line 290, in channel_authenticate_ssh
    self._ssh_message_handler(output=authenticate_buf)
  File "/opt/Training/python/automation_training/venv/lib/python3.8/site-packages/scrapli/channel/base_channel.py", line 432, in _ssh_message_handler
    raise ScrapliAuthenticationFailed(msg)
scrapli.exceptions.ScrapliAuthenticationFailed: b"\npermission denied, please try again.\ndoug@192.168.86.200's password: "

2022-10-20 11:54:57,880 - nornir.core.task -    ERROR -      start() - Host 'cart-colo': task 'credentials_test' failed with traceback:
Traceback (most recent call last):
  File "/opt/Training/python/automation_training/venv/lib/python3.8/site-packages/nornir/core/task.py", line 99, in start
    r = self.task(self, **self.params)
  File "script1.py", line 11, in credentials_test
    task.run(send_command, command="show ip int br")
  File "/opt/Training/python/automation_training/venv/lib/python3.8/site-packages/nornir/core/task.py", line 174, in run
    raise NornirSubTaskError(task=run_task, result=r)
nornir.core.exceptions.NornirSubTaskError: Subtask: send_command (failed)


2022-10-20 11:54:57,924 - nornir.core.task -    ERROR -      start() - Host 'ny5-feed-sw2': task 'send_command' failed with traceback:
Traceback (most recent call last):
  File "/opt/Training/python/automation_training/venv/lib/python3.8/site-packages/nornir/core/task.py", line 99, in start
    r = self.task(self, **self.params)
  File "/opt/Training/python/automation_training/venv/lib/python3.8/site-packages/nornir_scrapli/tasks/core/send_command.py", line 36, in send_command
    scrapli_conn = task.host.get_connection("scrapli", task.nornir.config)
  File "/opt/Training/python/automation_training/venv/lib/python3.8/site-packages/nornir/core/inventory.py", line 494, in get_connection
    self.open_connection(
  File "/opt/Training/python/automation_training/venv/lib/python3.8/site-packages/nornir/core/inventory.py", line 546, in open_connection
    conn_obj.open(
  File "/opt/Training/python/automation_training/venv/lib/python3.8/site-packages/nornir_scrapli/connection.py", line 105, in open
    connection.open()
  File "/opt/Training/python/automation_training/venv/lib/python3.8/site-packages/scrapli/driver/base/sync_driver.py", line 88, in open
    self.channel.channel_authenticate_ssh(
  File "/opt/Training/python/automation_training/venv/lib/python3.8/site-packages/scrapli/decorators.py", line 216, in decorate
    return _multiprocessing_timeout(
  File "/opt/Training/python/automation_training/venv/lib/python3.8/site-packages/scrapli/decorators.py", line 113, in _multiprocessing_timeout
    return future.result()
  File "/usr/lib/python3.8/concurrent/futures/_base.py", line 437, in result
    return self.__get_result()
  File "/usr/lib/python3.8/concurrent/futures/_base.py", line 389, in __get_result
    raise self._exception
  File "/usr/lib/python3.8/concurrent/futures/thread.py", line 57, in run
    result = self.fn(*self.args, **self.kwargs)
  File "/opt/Training/python/automation_training/venv/lib/python3.8/site-packages/scrapli/channel/sync_channel.py", line 302, in channel_authenticate_ssh
    raise ScrapliAuthenticationFailed(msg)
scrapli.exceptions.ScrapliAuthenticationFailed: password prompt seen more than once, assuming auth failed

2022-10-20 11:54:57,924 - nornir.core.task -    ERROR -      start() - Host 'ny5-feed-sw2': task 'credentials_test' failed with traceback:
Traceback (most recent call last):
  File "/opt/Training/python/automation_training/venv/lib/python3.8/site-packages/nornir/core/task.py", line 99, in start
    r = self.task(self, **self.params)
  File "script1.py", line 11, in credentials_test
    task.run(send_command, command="show ip int br")
  File "/opt/Training/python/automation_training/venv/lib/python3.8/site-packages/nornir/core/task.py", line 174, in run
    raise NornirSubTaskError(task=run_task, result=r)
nornir.core.exceptions.NornirSubTaskError: Subtask: send_command (failed)


2022-10-20 11:54:57,925 - nornir.core.task -    ERROR -      start() - Host 'ny5-feed-sw1a': task 'send_command' failed with traceback:
Traceback (most recent call last):
  File "/opt/Training/python/automation_training/venv/lib/python3.8/site-packages/nornir/core/task.py", line 99, in start
    r = self.task(self, **self.params)
  File "/opt/Training/python/automation_training/venv/lib/python3.8/site-packages/nornir_scrapli/tasks/core/send_command.py", line 36, in send_command
    scrapli_conn = task.host.get_connection("scrapli", task.nornir.config)
  File "/opt/Training/python/automation_training/venv/lib/python3.8/site-packages/nornir/core/inventory.py", line 494, in get_connection
    self.open_connection(
  File "/opt/Training/python/automation_training/venv/lib/python3.8/site-packages/nornir/core/inventory.py", line 546, in open_connection
    conn_obj.open(
  File "/opt/Training/python/automation_training/venv/lib/python3.8/site-packages/nornir_scrapli/connection.py", line 105, in open
    connection.open()
  File "/opt/Training/python/automation_training/venv/lib/python3.8/site-packages/scrapli/driver/base/sync_driver.py", line 88, in open
    self.channel.channel_authenticate_ssh(
  File "/opt/Training/python/automation_training/venv/lib/python3.8/site-packages/scrapli/decorators.py", line 216, in decorate
    return _multiprocessing_timeout(
  File "/opt/Training/python/automation_training/venv/lib/python3.8/site-packages/scrapli/decorators.py", line 113, in _multiprocessing_timeout
    return future.result()
  File "/usr/lib/python3.8/concurrent/futures/_base.py", line 437, in result
    return self.__get_result()
  File "/usr/lib/python3.8/concurrent/futures/_base.py", line 389, in __get_result
    raise self._exception
  File "/usr/lib/python3.8/concurrent/futures/thread.py", line 57, in run
    result = self.fn(*self.args, **self.kwargs)
  File "/opt/Training/python/automation_training/venv/lib/python3.8/site-packages/scrapli/channel/sync_channel.py", line 302, in channel_authenticate_ssh
    raise ScrapliAuthenticationFailed(msg)
scrapli.exceptions.ScrapliAuthenticationFailed: password prompt seen more than once, assuming auth failed

2022-10-20 11:54:57,925 - nornir.core.task -    ERROR -      start() - Host 'ny5-feed-sw1a': task 'credentials_test' failed with traceback:
Traceback (most recent call last):
  File "/opt/Training/python/automation_training/venv/lib/python3.8/site-packages/nornir/core/task.py", line 99, in start
    r = self.task(self, **self.params)
  File "script1.py", line 11, in credentials_test
    task.run(send_command, command="show ip int br")
  File "/opt/Training/python/automation_training/venv/lib/python3.8/site-packages/nornir/core/task.py", line 174, in run
    raise NornirSubTaskError(task=run_task, result=r)
nornir.core.exceptions.NornirSubTaskError: Subtask: send_command (failed)


2022-10-20 11:54:57,928 - nornir.core.task -    ERROR -      start() - Host 'ny5-feed-sw3': task 'send_command' failed with traceback:
Traceback (most recent call last):
  File "/opt/Training/python/automation_training/venv/lib/python3.8/site-packages/nornir/core/task.py", line 99, in start
    r = self.task(self, **self.params)
  File "/opt/Training/python/automation_training/venv/lib/python3.8/site-packages/nornir_scrapli/tasks/core/send_command.py", line 36, in send_command
    scrapli_conn = task.host.get_connection("scrapli", task.nornir.config)
  File "/opt/Training/python/automation_training/venv/lib/python3.8/site-packages/nornir/core/inventory.py", line 494, in get_connection
    self.open_connection(
  File "/opt/Training/python/automation_training/venv/lib/python3.8/site-packages/nornir/core/inventory.py", line 546, in open_connection
    conn_obj.open(
  File "/opt/Training/python/automation_training/venv/lib/python3.8/site-packages/nornir_scrapli/connection.py", line 105, in open
    connection.open()
  File "/opt/Training/python/automation_training/venv/lib/python3.8/site-packages/scrapli/driver/base/sync_driver.py", line 88, in open
    self.channel.channel_authenticate_ssh(
  File "/opt/Training/python/automation_training/venv/lib/python3.8/site-packages/scrapli/decorators.py", line 216, in decorate
    return _multiprocessing_timeout(
  File "/opt/Training/python/automation_training/venv/lib/python3.8/site-packages/scrapli/decorators.py", line 113, in _multiprocessing_timeout
    return future.result()
  File "/usr/lib/python3.8/concurrent/futures/_base.py", line 437, in result
    return self.__get_result()
  File "/usr/lib/python3.8/concurrent/futures/_base.py", line 389, in __get_result
    raise self._exception
  File "/usr/lib/python3.8/concurrent/futures/thread.py", line 57, in run
    result = self.fn(*self.args, **self.kwargs)
  File "/opt/Training/python/automation_training/venv/lib/python3.8/site-packages/scrapli/channel/sync_channel.py", line 302, in channel_authenticate_ssh
    raise ScrapliAuthenticationFailed(msg)
scrapli.exceptions.ScrapliAuthenticationFailed: password prompt seen more than once, assuming auth failed

2022-10-20 11:54:57,929 - nornir.core.task -    ERROR -      start() - Host 'ny5-feed-sw3': task 'credentials_test' failed with traceback:
Traceback (most recent call last):
  File "/opt/Training/python/automation_training/venv/lib/python3.8/site-packages/nornir/core/task.py", line 99, in start
    r = self.task(self, **self.params)
  File "script1.py", line 11, in credentials_test
    task.run(send_command, command="show ip int br")
  File "/opt/Training/python/automation_training/venv/lib/python3.8/site-packages/nornir/core/task.py", line 174, in run
    raise NornirSubTaskError(task=run_task, result=r)
nornir.core.exceptions.NornirSubTaskError: Subtask: send_command (failed)


2022-10-20 11:54:57,962 - nornir.core.task -    ERROR -      start() - Host 'ny5-feed-sw1b': task 'send_command' failed with traceback:
Traceback (most recent call last):
  File "/opt/Training/python/automation_training/venv/lib/python3.8/site-packages/nornir/core/task.py", line 99, in start
    r = self.task(self, **self.params)
  File "/opt/Training/python/automation_training/venv/lib/python3.8/site-packages/nornir_scrapli/tasks/core/send_command.py", line 36, in send_command
    scrapli_conn = task.host.get_connection("scrapli", task.nornir.config)
  File "/opt/Training/python/automation_training/venv/lib/python3.8/site-packages/nornir/core/inventory.py", line 494, in get_connection
    self.open_connection(
  File "/opt/Training/python/automation_training/venv/lib/python3.8/site-packages/nornir/core/inventory.py", line 546, in open_connection
    conn_obj.open(
  File "/opt/Training/python/automation_training/venv/lib/python3.8/site-packages/nornir_scrapli/connection.py", line 105, in open
    connection.open()
  File "/opt/Training/python/automation_training/venv/lib/python3.8/site-packages/scrapli/driver/base/sync_driver.py", line 88, in open
    self.channel.channel_authenticate_ssh(
  File "/opt/Training/python/automation_training/venv/lib/python3.8/site-packages/scrapli/decorators.py", line 216, in decorate
    return _multiprocessing_timeout(
  File "/opt/Training/python/automation_training/venv/lib/python3.8/site-packages/scrapli/decorators.py", line 113, in _multiprocessing_timeout
    return future.result()
  File "/usr/lib/python3.8/concurrent/futures/_base.py", line 437, in result
    return self.__get_result()
  File "/usr/lib/python3.8/concurrent/futures/_base.py", line 389, in __get_result
    raise self._exception
  File "/usr/lib/python3.8/concurrent/futures/thread.py", line 57, in run
    result = self.fn(*self.args, **self.kwargs)
  File "/opt/Training/python/automation_training/venv/lib/python3.8/site-packages/scrapli/channel/sync_channel.py", line 302, in channel_authenticate_ssh
    raise ScrapliAuthenticationFailed(msg)
scrapli.exceptions.ScrapliAuthenticationFailed: password prompt seen more than once, assuming auth failed

2022-10-20 11:54:57,962 - nornir.core.task -    ERROR -      start() - Host 'ny5-feed-sw1b': task 'credentials_test' failed with traceback:
Traceback (most recent call last):
  File "/opt/Training/python/automation_training/venv/lib/python3.8/site-packages/nornir/core/task.py", line 99, in start
    r = self.task(self, **self.params)
  File "script1.py", line 11, in credentials_test
    task.run(send_command, command="show ip int br")
  File "/opt/Training/python/automation_training/venv/lib/python3.8/site-packages/nornir/core/task.py", line 174, in run
    raise NornirSubTaskError(task=run_task, result=r)
nornir.core.exceptions.NornirSubTaskError: Subtask: send_command (failed)


2022-10-20 11:54:57,981 - nornir.core.task -    ERROR -      start() - Host 'telx-colo': task 'send_command' failed with traceback:
Traceback (most recent call last):
  File "/opt/Training/python/automation_training/venv/lib/python3.8/site-packages/nornir/core/task.py", line 99, in start
    r = self.task(self, **self.params)
  File "/opt/Training/python/automation_training/venv/lib/python3.8/site-packages/nornir_scrapli/tasks/core/send_command.py", line 36, in send_command
    scrapli_conn = task.host.get_connection("scrapli", task.nornir.config)
  File "/opt/Training/python/automation_training/venv/lib/python3.8/site-packages/nornir/core/inventory.py", line 494, in get_connection
    self.open_connection(
  File "/opt/Training/python/automation_training/venv/lib/python3.8/site-packages/nornir/core/inventory.py", line 546, in open_connection
    conn_obj.open(
  File "/opt/Training/python/automation_training/venv/lib/python3.8/site-packages/nornir_scrapli/connection.py", line 105, in open
    connection.open()
  File "/opt/Training/python/automation_training/venv/lib/python3.8/site-packages/scrapli/driver/base/sync_driver.py", line 88, in open
    self.channel.channel_authenticate_ssh(
  File "/opt/Training/python/automation_training/venv/lib/python3.8/site-packages/scrapli/decorators.py", line 216, in decorate
    return _multiprocessing_timeout(
  File "/opt/Training/python/automation_training/venv/lib/python3.8/site-packages/scrapli/decorators.py", line 113, in _multiprocessing_timeout
    return future.result()
  File "/usr/lib/python3.8/concurrent/futures/_base.py", line 437, in result
    return self.__get_result()
  File "/usr/lib/python3.8/concurrent/futures/_base.py", line 389, in __get_result
    raise self._exception
  File "/usr/lib/python3.8/concurrent/futures/thread.py", line 57, in run
    result = self.fn(*self.args, **self.kwargs)
  File "/opt/Training/python/automation_training/venv/lib/python3.8/site-packages/scrapli/channel/sync_channel.py", line 302, in channel_authenticate_ssh
    raise ScrapliAuthenticationFailed(msg)
scrapli.exceptions.ScrapliAuthenticationFailed: password prompt seen more than once, assuming auth failed

2022-10-20 11:54:57,981 - nornir.core.task -    ERROR -      start() - Host 'telx-colo': task 'credentials_test' failed with traceback:
Traceback (most recent call last):
  File "/opt/Training/python/automation_training/venv/lib/python3.8/site-packages/nornir/core/task.py", line 99, in start
    r = self.task(self, **self.params)
  File "script1.py", line 11, in credentials_test
    task.run(send_command, command="show ip int br")
  File "/opt/Training/python/automation_training/venv/lib/python3.8/site-packages/nornir/core/task.py", line 174, in run
    raise NornirSubTaskError(task=run_task, result=r)
nornir.core.exceptions.NornirSubTaskError: Subtask: send_command (failed)


2022-10-20 11:55:21,871 -  nornir.core -     INFO -        run() - Running task 'credentials_test' with args {} on 6 hosts
2022-10-20 12:00:51,137 -  nornir.core -     INFO -        run() - Running task 'credentials_test' with args {} on 6 hosts
2022-10-20 12:00:51,468 - nornir.core.task -    ERROR -      start() - Host 'cart-colo': task 'send_command' failed with traceback:
Traceback (most recent call last):
  File "/opt/Training/python/automation_training/venv/lib/python3.8/site-packages/nornir/core/task.py", line 99, in start
    r = self.task(self, **self.params)
  File "/opt/Training/python/automation_training/venv/lib/python3.8/site-packages/nornir_scrapli/tasks/core/send_command.py", line 36, in send_command
    scrapli_conn = task.host.get_connection("scrapli", task.nornir.config)
  File "/opt/Training/python/automation_training/venv/lib/python3.8/site-packages/nornir/core/inventory.py", line 494, in get_connection
    self.open_connection(
  File "/opt/Training/python/automation_training/venv/lib/python3.8/site-packages/nornir/core/inventory.py", line 546, in open_connection
    conn_obj.open(
  File "/opt/Training/python/automation_training/venv/lib/python3.8/site-packages/nornir_scrapli/connection.py", line 105, in open
    connection.open()
  File "/opt/Training/python/automation_training/venv/lib/python3.8/site-packages/scrapli/driver/base/sync_driver.py", line 88, in open
    self.channel.channel_authenticate_ssh(
  File "/opt/Training/python/automation_training/venv/lib/python3.8/site-packages/scrapli/decorators.py", line 216, in decorate
    return _multiprocessing_timeout(
  File "/opt/Training/python/automation_training/venv/lib/python3.8/site-packages/scrapli/decorators.py", line 113, in _multiprocessing_timeout
    return future.result()
  File "/usr/lib/python3.8/concurrent/futures/_base.py", line 437, in result
    return self.__get_result()
  File "/usr/lib/python3.8/concurrent/futures/_base.py", line 389, in __get_result
    raise self._exception
  File "/usr/lib/python3.8/concurrent/futures/thread.py", line 57, in run
    result = self.fn(*self.args, **self.kwargs)
  File "/opt/Training/python/automation_training/venv/lib/python3.8/site-packages/scrapli/channel/sync_channel.py", line 290, in channel_authenticate_ssh
    self._ssh_message_handler(output=authenticate_buf)
  File "/opt/Training/python/automation_training/venv/lib/python3.8/site-packages/scrapli/channel/base_channel.py", line 432, in _ssh_message_handler
    raise ScrapliAuthenticationFailed(msg)
scrapli.exceptions.ScrapliAuthenticationFailed: b"\npermission denied, please try again.\narista@192.168.86.200's password: "

2022-10-20 12:00:51,469 - nornir.core.task -    ERROR -      start() - Host 'cart-colo': task 'credentials_test' failed with traceback:
Traceback (most recent call last):
  File "/opt/Training/python/automation_training/venv/lib/python3.8/site-packages/nornir/core/task.py", line 99, in start
    r = self.task(self, **self.params)
  File "script2.py", line 9, in credentials_test
    task.run(send_command, command="show ip int br")
  File "/opt/Training/python/automation_training/venv/lib/python3.8/site-packages/nornir/core/task.py", line 174, in run
    raise NornirSubTaskError(task=run_task, result=r)
nornir.core.exceptions.NornirSubTaskError: Subtask: send_command (failed)


2022-10-20 12:00:51,516 - nornir.core.task -    ERROR -      start() - Host 'ny5-feed-sw1a': task 'send_command' failed with traceback:
Traceback (most recent call last):
  File "/opt/Training/python/automation_training/venv/lib/python3.8/site-packages/nornir/core/task.py", line 99, in start
    r = self.task(self, **self.params)
  File "/opt/Training/python/automation_training/venv/lib/python3.8/site-packages/nornir_scrapli/tasks/core/send_command.py", line 36, in send_command
    scrapli_conn = task.host.get_connection("scrapli", task.nornir.config)
  File "/opt/Training/python/automation_training/venv/lib/python3.8/site-packages/nornir/core/inventory.py", line 494, in get_connection
    self.open_connection(
  File "/opt/Training/python/automation_training/venv/lib/python3.8/site-packages/nornir/core/inventory.py", line 546, in open_connection
    conn_obj.open(
  File "/opt/Training/python/automation_training/venv/lib/python3.8/site-packages/nornir_scrapli/connection.py", line 105, in open
    connection.open()
  File "/opt/Training/python/automation_training/venv/lib/python3.8/site-packages/scrapli/driver/base/sync_driver.py", line 88, in open
    self.channel.channel_authenticate_ssh(
  File "/opt/Training/python/automation_training/venv/lib/python3.8/site-packages/scrapli/decorators.py", line 216, in decorate
    return _multiprocessing_timeout(
  File "/opt/Training/python/automation_training/venv/lib/python3.8/site-packages/scrapli/decorators.py", line 113, in _multiprocessing_timeout
    return future.result()
  File "/usr/lib/python3.8/concurrent/futures/_base.py", line 437, in result
    return self.__get_result()
  File "/usr/lib/python3.8/concurrent/futures/_base.py", line 389, in __get_result
    raise self._exception
  File "/usr/lib/python3.8/concurrent/futures/thread.py", line 57, in run
    result = self.fn(*self.args, **self.kwargs)
  File "/opt/Training/python/automation_training/venv/lib/python3.8/site-packages/scrapli/channel/sync_channel.py", line 302, in channel_authenticate_ssh
    raise ScrapliAuthenticationFailed(msg)
scrapli.exceptions.ScrapliAuthenticationFailed: password prompt seen more than once, assuming auth failed

2022-10-20 12:00:51,516 - nornir.core.task -    ERROR -      start() - Host 'ny5-feed-sw1a': task 'credentials_test' failed with traceback:
Traceback (most recent call last):
  File "/opt/Training/python/automation_training/venv/lib/python3.8/site-packages/nornir/core/task.py", line 99, in start
    r = self.task(self, **self.params)
  File "script2.py", line 9, in credentials_test
    task.run(send_command, command="show ip int br")
  File "/opt/Training/python/automation_training/venv/lib/python3.8/site-packages/nornir/core/task.py", line 174, in run
    raise NornirSubTaskError(task=run_task, result=r)
nornir.core.exceptions.NornirSubTaskError: Subtask: send_command (failed)


2022-10-20 12:00:51,522 - nornir.core.task -    ERROR -      start() - Host 'ny5-feed-sw1b': task 'send_command' failed with traceback:
Traceback (most recent call last):
  File "/opt/Training/python/automation_training/venv/lib/python3.8/site-packages/nornir/core/task.py", line 99, in start
    r = self.task(self, **self.params)
  File "/opt/Training/python/automation_training/venv/lib/python3.8/site-packages/nornir_scrapli/tasks/core/send_command.py", line 36, in send_command
    scrapli_conn = task.host.get_connection("scrapli", task.nornir.config)
  File "/opt/Training/python/automation_training/venv/lib/python3.8/site-packages/nornir/core/inventory.py", line 494, in get_connection
    self.open_connection(
  File "/opt/Training/python/automation_training/venv/lib/python3.8/site-packages/nornir/core/inventory.py", line 546, in open_connection
    conn_obj.open(
  File "/opt/Training/python/automation_training/venv/lib/python3.8/site-packages/nornir_scrapli/connection.py", line 105, in open
    connection.open()
  File "/opt/Training/python/automation_training/venv/lib/python3.8/site-packages/scrapli/driver/base/sync_driver.py", line 88, in open
    self.channel.channel_authenticate_ssh(
  File "/opt/Training/python/automation_training/venv/lib/python3.8/site-packages/scrapli/decorators.py", line 216, in decorate
    return _multiprocessing_timeout(
  File "/opt/Training/python/automation_training/venv/lib/python3.8/site-packages/scrapli/decorators.py", line 113, in _multiprocessing_timeout
    return future.result()
  File "/usr/lib/python3.8/concurrent/futures/_base.py", line 437, in result
    return self.__get_result()
  File "/usr/lib/python3.8/concurrent/futures/_base.py", line 389, in __get_result
    raise self._exception
  File "/usr/lib/python3.8/concurrent/futures/thread.py", line 57, in run
    result = self.fn(*self.args, **self.kwargs)
  File "/opt/Training/python/automation_training/venv/lib/python3.8/site-packages/scrapli/channel/sync_channel.py", line 302, in channel_authenticate_ssh
    raise ScrapliAuthenticationFailed(msg)
scrapli.exceptions.ScrapliAuthenticationFailed: password prompt seen more than once, assuming auth failed

2022-10-20 12:00:51,522 - nornir.core.task -    ERROR -      start() - Host 'ny5-feed-sw1b': task 'credentials_test' failed with traceback:
Traceback (most recent call last):
  File "/opt/Training/python/automation_training/venv/lib/python3.8/site-packages/nornir/core/task.py", line 99, in start
    r = self.task(self, **self.params)
  File "script2.py", line 9, in credentials_test
    task.run(send_command, command="show ip int br")
  File "/opt/Training/python/automation_training/venv/lib/python3.8/site-packages/nornir/core/task.py", line 174, in run
    raise NornirSubTaskError(task=run_task, result=r)
nornir.core.exceptions.NornirSubTaskError: Subtask: send_command (failed)


2022-10-20 12:00:51,536 - nornir.core.task -    ERROR -      start() - Host 'telx-colo': task 'send_command' failed with traceback:
Traceback (most recent call last):
  File "/opt/Training/python/automation_training/venv/lib/python3.8/site-packages/nornir/core/task.py", line 99, in start
    r = self.task(self, **self.params)
  File "/opt/Training/python/automation_training/venv/lib/python3.8/site-packages/nornir_scrapli/tasks/core/send_command.py", line 36, in send_command
    scrapli_conn = task.host.get_connection("scrapli", task.nornir.config)
  File "/opt/Training/python/automation_training/venv/lib/python3.8/site-packages/nornir/core/inventory.py", line 494, in get_connection
    self.open_connection(
  File "/opt/Training/python/automation_training/venv/lib/python3.8/site-packages/nornir/core/inventory.py", line 546, in open_connection
    conn_obj.open(
  File "/opt/Training/python/automation_training/venv/lib/python3.8/site-packages/nornir_scrapli/connection.py", line 105, in open
    connection.open()
  File "/opt/Training/python/automation_training/venv/lib/python3.8/site-packages/scrapli/driver/base/sync_driver.py", line 88, in open
    self.channel.channel_authenticate_ssh(
  File "/opt/Training/python/automation_training/venv/lib/python3.8/site-packages/scrapli/decorators.py", line 216, in decorate
    return _multiprocessing_timeout(
  File "/opt/Training/python/automation_training/venv/lib/python3.8/site-packages/scrapli/decorators.py", line 113, in _multiprocessing_timeout
    return future.result()
  File "/usr/lib/python3.8/concurrent/futures/_base.py", line 437, in result
    return self.__get_result()
  File "/usr/lib/python3.8/concurrent/futures/_base.py", line 389, in __get_result
    raise self._exception
  File "/usr/lib/python3.8/concurrent/futures/thread.py", line 57, in run
    result = self.fn(*self.args, **self.kwargs)
  File "/opt/Training/python/automation_training/venv/lib/python3.8/site-packages/scrapli/channel/sync_channel.py", line 302, in channel_authenticate_ssh
    raise ScrapliAuthenticationFailed(msg)
scrapli.exceptions.ScrapliAuthenticationFailed: password prompt seen more than once, assuming auth failed

2022-10-20 12:00:51,536 - nornir.core.task -    ERROR -      start() - Host 'telx-colo': task 'credentials_test' failed with traceback:
Traceback (most recent call last):
  File "/opt/Training/python/automation_training/venv/lib/python3.8/site-packages/nornir/core/task.py", line 99, in start
    r = self.task(self, **self.params)
  File "script2.py", line 9, in credentials_test
    task.run(send_command, command="show ip int br")
  File "/opt/Training/python/automation_training/venv/lib/python3.8/site-packages/nornir/core/task.py", line 174, in run
    raise NornirSubTaskError(task=run_task, result=r)
nornir.core.exceptions.NornirSubTaskError: Subtask: send_command (failed)


2022-10-20 12:00:51,539 - nornir.core.task -    ERROR -      start() - Host 'ny5-feed-sw3': task 'send_command' failed with traceback:
Traceback (most recent call last):
  File "/opt/Training/python/automation_training/venv/lib/python3.8/site-packages/nornir/core/task.py", line 99, in start
    r = self.task(self, **self.params)
  File "/opt/Training/python/automation_training/venv/lib/python3.8/site-packages/nornir_scrapli/tasks/core/send_command.py", line 36, in send_command
    scrapli_conn = task.host.get_connection("scrapli", task.nornir.config)
  File "/opt/Training/python/automation_training/venv/lib/python3.8/site-packages/nornir/core/inventory.py", line 494, in get_connection
    self.open_connection(
  File "/opt/Training/python/automation_training/venv/lib/python3.8/site-packages/nornir/core/inventory.py", line 546, in open_connection
    conn_obj.open(
  File "/opt/Training/python/automation_training/venv/lib/python3.8/site-packages/nornir_scrapli/connection.py", line 105, in open
    connection.open()
  File "/opt/Training/python/automation_training/venv/lib/python3.8/site-packages/scrapli/driver/base/sync_driver.py", line 88, in open
    self.channel.channel_authenticate_ssh(
  File "/opt/Training/python/automation_training/venv/lib/python3.8/site-packages/scrapli/decorators.py", line 216, in decorate
    return _multiprocessing_timeout(
  File "/opt/Training/python/automation_training/venv/lib/python3.8/site-packages/scrapli/decorators.py", line 113, in _multiprocessing_timeout
    return future.result()
  File "/usr/lib/python3.8/concurrent/futures/_base.py", line 437, in result
    return self.__get_result()
  File "/usr/lib/python3.8/concurrent/futures/_base.py", line 389, in __get_result
    raise self._exception
  File "/usr/lib/python3.8/concurrent/futures/thread.py", line 57, in run
    result = self.fn(*self.args, **self.kwargs)
  File "/opt/Training/python/automation_training/venv/lib/python3.8/site-packages/scrapli/channel/sync_channel.py", line 302, in channel_authenticate_ssh
    raise ScrapliAuthenticationFailed(msg)
scrapli.exceptions.ScrapliAuthenticationFailed: password prompt seen more than once, assuming auth failed

2022-10-20 12:00:51,539 - nornir.core.task -    ERROR -      start() - Host 'ny5-feed-sw3': task 'credentials_test' failed with traceback:
Traceback (most recent call last):
  File "/opt/Training/python/automation_training/venv/lib/python3.8/site-packages/nornir/core/task.py", line 99, in start
    r = self.task(self, **self.params)
  File "script2.py", line 9, in credentials_test
    task.run(send_command, command="show ip int br")
  File "/opt/Training/python/automation_training/venv/lib/python3.8/site-packages/nornir/core/task.py", line 174, in run
    raise NornirSubTaskError(task=run_task, result=r)
nornir.core.exceptions.NornirSubTaskError: Subtask: send_command (failed)


2022-10-20 12:00:51,548 - nornir.core.task -    ERROR -      start() - Host 'ny5-feed-sw2': task 'send_command' failed with traceback:
Traceback (most recent call last):
  File "/opt/Training/python/automation_training/venv/lib/python3.8/site-packages/nornir/core/task.py", line 99, in start
    r = self.task(self, **self.params)
  File "/opt/Training/python/automation_training/venv/lib/python3.8/site-packages/nornir_scrapli/tasks/core/send_command.py", line 36, in send_command
    scrapli_conn = task.host.get_connection("scrapli", task.nornir.config)
  File "/opt/Training/python/automation_training/venv/lib/python3.8/site-packages/nornir/core/inventory.py", line 494, in get_connection
    self.open_connection(
  File "/opt/Training/python/automation_training/venv/lib/python3.8/site-packages/nornir/core/inventory.py", line 546, in open_connection
    conn_obj.open(
  File "/opt/Training/python/automation_training/venv/lib/python3.8/site-packages/nornir_scrapli/connection.py", line 105, in open
    connection.open()
  File "/opt/Training/python/automation_training/venv/lib/python3.8/site-packages/scrapli/driver/base/sync_driver.py", line 88, in open
    self.channel.channel_authenticate_ssh(
  File "/opt/Training/python/automation_training/venv/lib/python3.8/site-packages/scrapli/decorators.py", line 216, in decorate
    return _multiprocessing_timeout(
  File "/opt/Training/python/automation_training/venv/lib/python3.8/site-packages/scrapli/decorators.py", line 113, in _multiprocessing_timeout
    return future.result()
  File "/usr/lib/python3.8/concurrent/futures/_base.py", line 437, in result
    return self.__get_result()
  File "/usr/lib/python3.8/concurrent/futures/_base.py", line 389, in __get_result
    raise self._exception
  File "/usr/lib/python3.8/concurrent/futures/thread.py", line 57, in run
    result = self.fn(*self.args, **self.kwargs)
  File "/opt/Training/python/automation_training/venv/lib/python3.8/site-packages/scrapli/channel/sync_channel.py", line 302, in channel_authenticate_ssh
    raise ScrapliAuthenticationFailed(msg)
scrapli.exceptions.ScrapliAuthenticationFailed: password prompt seen more than once, assuming auth failed

2022-10-20 12:00:51,548 - nornir.core.task -    ERROR -      start() - Host 'ny5-feed-sw2': task 'credentials_test' failed with traceback:
Traceback (most recent call last):
  File "/opt/Training/python/automation_training/venv/lib/python3.8/site-packages/nornir/core/task.py", line 99, in start
    r = self.task(self, **self.params)
  File "script2.py", line 9, in credentials_test
    task.run(send_command, command="show ip int br")
  File "/opt/Training/python/automation_training/venv/lib/python3.8/site-packages/nornir/core/task.py", line 174, in run
    raise NornirSubTaskError(task=run_task, result=r)
nornir.core.exceptions.NornirSubTaskError: Subtask: send_command (failed)


2022-10-21 09:54:29,647 -  nornir.core -     INFO -        run() - Running task 'credentials_test' with args {} on 6 hosts
2022-10-21 09:54:30,023 - nornir.core.task -    ERROR -      start() - Host 'ny5-feed-sw1a': task 'send_command' failed with traceback:
Traceback (most recent call last):
  File "/opt/Training/python/automation_training/venv/lib/python3.8/site-packages/nornir/core/task.py", line 99, in start
    r = self.task(self, **self.params)
  File "/opt/Training/python/automation_training/venv/lib/python3.8/site-packages/nornir_scrapli/tasks/core/send_command.py", line 36, in send_command
    scrapli_conn = task.host.get_connection("scrapli", task.nornir.config)
  File "/opt/Training/python/automation_training/venv/lib/python3.8/site-packages/nornir/core/inventory.py", line 494, in get_connection
    self.open_connection(
  File "/opt/Training/python/automation_training/venv/lib/python3.8/site-packages/nornir/core/inventory.py", line 546, in open_connection
    conn_obj.open(
  File "/opt/Training/python/automation_training/venv/lib/python3.8/site-packages/nornir_scrapli/connection.py", line 105, in open
    connection.open()
  File "/opt/Training/python/automation_training/venv/lib/python3.8/site-packages/scrapli/driver/base/sync_driver.py", line 88, in open
    self.channel.channel_authenticate_ssh(
  File "/opt/Training/python/automation_training/venv/lib/python3.8/site-packages/scrapli/decorators.py", line 216, in decorate
    return _multiprocessing_timeout(
  File "/opt/Training/python/automation_training/venv/lib/python3.8/site-packages/scrapli/decorators.py", line 113, in _multiprocessing_timeout
    return future.result()
  File "/usr/lib/python3.8/concurrent/futures/_base.py", line 437, in result
    return self.__get_result()
  File "/usr/lib/python3.8/concurrent/futures/_base.py", line 389, in __get_result
    raise self._exception
  File "/usr/lib/python3.8/concurrent/futures/thread.py", line 57, in run
    result = self.fn(*self.args, **self.kwargs)
  File "/opt/Training/python/automation_training/venv/lib/python3.8/site-packages/scrapli/channel/sync_channel.py", line 302, in channel_authenticate_ssh
    raise ScrapliAuthenticationFailed(msg)
scrapli.exceptions.ScrapliAuthenticationFailed: password prompt seen more than once, assuming auth failed

2022-10-21 09:54:30,024 - nornir.core.task -    ERROR -      start() - Host 'ny5-feed-sw1a': task 'credentials_test' failed with traceback:
Traceback (most recent call last):
  File "/opt/Training/python/automation_training/venv/lib/python3.8/site-packages/nornir/core/task.py", line 99, in start
    r = self.task(self, **self.params)
  File "script2.py", line 9, in credentials_test
    task.run(send_command, command="show ip int br")
  File "/opt/Training/python/automation_training/venv/lib/python3.8/site-packages/nornir/core/task.py", line 174, in run
    raise NornirSubTaskError(task=run_task, result=r)
nornir.core.exceptions.NornirSubTaskError: Subtask: send_command (failed)


2022-10-21 09:54:30,034 - nornir.core.task -    ERROR -      start() - Host 'ny5-feed-sw3': task 'send_command' failed with traceback:
Traceback (most recent call last):
  File "/opt/Training/python/automation_training/venv/lib/python3.8/site-packages/nornir/core/task.py", line 99, in start
    r = self.task(self, **self.params)
  File "/opt/Training/python/automation_training/venv/lib/python3.8/site-packages/nornir_scrapli/tasks/core/send_command.py", line 36, in send_command
    scrapli_conn = task.host.get_connection("scrapli", task.nornir.config)
  File "/opt/Training/python/automation_training/venv/lib/python3.8/site-packages/nornir/core/inventory.py", line 494, in get_connection
    self.open_connection(
  File "/opt/Training/python/automation_training/venv/lib/python3.8/site-packages/nornir/core/inventory.py", line 546, in open_connection
    conn_obj.open(
  File "/opt/Training/python/automation_training/venv/lib/python3.8/site-packages/nornir_scrapli/connection.py", line 105, in open
    connection.open()
  File "/opt/Training/python/automation_training/venv/lib/python3.8/site-packages/scrapli/driver/base/sync_driver.py", line 88, in open
    self.channel.channel_authenticate_ssh(
  File "/opt/Training/python/automation_training/venv/lib/python3.8/site-packages/scrapli/decorators.py", line 216, in decorate
    return _multiprocessing_timeout(
  File "/opt/Training/python/automation_training/venv/lib/python3.8/site-packages/scrapli/decorators.py", line 113, in _multiprocessing_timeout
    return future.result()
  File "/usr/lib/python3.8/concurrent/futures/_base.py", line 437, in result
    return self.__get_result()
  File "/usr/lib/python3.8/concurrent/futures/_base.py", line 389, in __get_result
    raise self._exception
  File "/usr/lib/python3.8/concurrent/futures/thread.py", line 57, in run
    result = self.fn(*self.args, **self.kwargs)
  File "/opt/Training/python/automation_training/venv/lib/python3.8/site-packages/scrapli/channel/sync_channel.py", line 302, in channel_authenticate_ssh
    raise ScrapliAuthenticationFailed(msg)
scrapli.exceptions.ScrapliAuthenticationFailed: password prompt seen more than once, assuming auth failed

2022-10-21 09:54:30,034 - nornir.core.task -    ERROR -      start() - Host 'ny5-feed-sw3': task 'credentials_test' failed with traceback:
Traceback (most recent call last):
  File "/opt/Training/python/automation_training/venv/lib/python3.8/site-packages/nornir/core/task.py", line 99, in start
    r = self.task(self, **self.params)
  File "script2.py", line 9, in credentials_test
    task.run(send_command, command="show ip int br")
  File "/opt/Training/python/automation_training/venv/lib/python3.8/site-packages/nornir/core/task.py", line 174, in run
    raise NornirSubTaskError(task=run_task, result=r)
nornir.core.exceptions.NornirSubTaskError: Subtask: send_command (failed)


2022-10-21 09:54:30,067 - nornir.core.task -    ERROR -      start() - Host 'ny5-feed-sw1b': task 'send_command' failed with traceback:
Traceback (most recent call last):
  File "/opt/Training/python/automation_training/venv/lib/python3.8/site-packages/nornir/core/task.py", line 99, in start
    r = self.task(self, **self.params)
  File "/opt/Training/python/automation_training/venv/lib/python3.8/site-packages/nornir_scrapli/tasks/core/send_command.py", line 36, in send_command
    scrapli_conn = task.host.get_connection("scrapli", task.nornir.config)
  File "/opt/Training/python/automation_training/venv/lib/python3.8/site-packages/nornir/core/inventory.py", line 494, in get_connection
    self.open_connection(
  File "/opt/Training/python/automation_training/venv/lib/python3.8/site-packages/nornir/core/inventory.py", line 546, in open_connection
    conn_obj.open(
  File "/opt/Training/python/automation_training/venv/lib/python3.8/site-packages/nornir_scrapli/connection.py", line 105, in open
    connection.open()
  File "/opt/Training/python/automation_training/venv/lib/python3.8/site-packages/scrapli/driver/base/sync_driver.py", line 88, in open
    self.channel.channel_authenticate_ssh(
  File "/opt/Training/python/automation_training/venv/lib/python3.8/site-packages/scrapli/decorators.py", line 216, in decorate
    return _multiprocessing_timeout(
  File "/opt/Training/python/automation_training/venv/lib/python3.8/site-packages/scrapli/decorators.py", line 113, in _multiprocessing_timeout
    return future.result()
  File "/usr/lib/python3.8/concurrent/futures/_base.py", line 437, in result
    return self.__get_result()
  File "/usr/lib/python3.8/concurrent/futures/_base.py", line 389, in __get_result
    raise self._exception
  File "/usr/lib/python3.8/concurrent/futures/thread.py", line 57, in run
    result = self.fn(*self.args, **self.kwargs)
  File "/opt/Training/python/automation_training/venv/lib/python3.8/site-packages/scrapli/channel/sync_channel.py", line 302, in channel_authenticate_ssh
    raise ScrapliAuthenticationFailed(msg)
scrapli.exceptions.ScrapliAuthenticationFailed: password prompt seen more than once, assuming auth failed

2022-10-21 09:54:30,067 - nornir.core.task -    ERROR -      start() - Host 'ny5-feed-sw1b': task 'credentials_test' failed with traceback:
Traceback (most recent call last):
  File "/opt/Training/python/automation_training/venv/lib/python3.8/site-packages/nornir/core/task.py", line 99, in start
    r = self.task(self, **self.params)
  File "script2.py", line 9, in credentials_test
    task.run(send_command, command="show ip int br")
  File "/opt/Training/python/automation_training/venv/lib/python3.8/site-packages/nornir/core/task.py", line 174, in run
    raise NornirSubTaskError(task=run_task, result=r)
nornir.core.exceptions.NornirSubTaskError: Subtask: send_command (failed)


2022-10-21 09:54:34,504 - nornir.core.task -    ERROR -      start() - Host 'ny5-feed-sw2': task 'send_command' failed with traceback:
Traceback (most recent call last):
  File "/opt/Training/python/automation_training/venv/lib/python3.8/site-packages/nornir/core/task.py", line 99, in start
    r = self.task(self, **self.params)
  File "/opt/Training/python/automation_training/venv/lib/python3.8/site-packages/nornir_scrapli/tasks/core/send_command.py", line 36, in send_command
    scrapli_conn = task.host.get_connection("scrapli", task.nornir.config)
  File "/opt/Training/python/automation_training/venv/lib/python3.8/site-packages/nornir/core/inventory.py", line 494, in get_connection
    self.open_connection(
  File "/opt/Training/python/automation_training/venv/lib/python3.8/site-packages/nornir/core/inventory.py", line 546, in open_connection
    conn_obj.open(
  File "/opt/Training/python/automation_training/venv/lib/python3.8/site-packages/nornir_scrapli/connection.py", line 105, in open
    connection.open()
  File "/opt/Training/python/automation_training/venv/lib/python3.8/site-packages/scrapli/driver/base/sync_driver.py", line 88, in open
    self.channel.channel_authenticate_ssh(
  File "/opt/Training/python/automation_training/venv/lib/python3.8/site-packages/scrapli/decorators.py", line 216, in decorate
    return _multiprocessing_timeout(
  File "/opt/Training/python/automation_training/venv/lib/python3.8/site-packages/scrapli/decorators.py", line 113, in _multiprocessing_timeout
    return future.result()
  File "/usr/lib/python3.8/concurrent/futures/_base.py", line 437, in result
    return self.__get_result()
  File "/usr/lib/python3.8/concurrent/futures/_base.py", line 389, in __get_result
    raise self._exception
  File "/usr/lib/python3.8/concurrent/futures/thread.py", line 57, in run
    result = self.fn(*self.args, **self.kwargs)
  File "/opt/Training/python/automation_training/venv/lib/python3.8/site-packages/scrapli/channel/sync_channel.py", line 302, in channel_authenticate_ssh
    raise ScrapliAuthenticationFailed(msg)
scrapli.exceptions.ScrapliAuthenticationFailed: password prompt seen more than once, assuming auth failed

2022-10-21 09:54:34,504 - nornir.core.task -    ERROR -      start() - Host 'ny5-feed-sw2': task 'credentials_test' failed with traceback:
Traceback (most recent call last):
  File "/opt/Training/python/automation_training/venv/lib/python3.8/site-packages/nornir/core/task.py", line 99, in start
    r = self.task(self, **self.params)
  File "script2.py", line 9, in credentials_test
    task.run(send_command, command="show ip int br")
  File "/opt/Training/python/automation_training/venv/lib/python3.8/site-packages/nornir/core/task.py", line 174, in run
    raise NornirSubTaskError(task=run_task, result=r)
nornir.core.exceptions.NornirSubTaskError: Subtask: send_command (failed)


2022-10-21 09:54:57,305 -  nornir.core -     INFO -        run() - Running task 'credentials_test' with args {} on 6 hosts
2022-10-21 09:55:14,451 -  nornir.core -     INFO -        run() - Running task 'credentials_test' with args {} on 6 hosts
2022-10-21 10:00:44,912 -  nornir.core -     INFO -        run() - Running task 'credentials_test' with args {} on 6 hosts
2022-10-21 10:00:45,346 - nornir.core.task -    ERROR -      start() - Host 'cart-colo': task 'send_command' failed with traceback:
Traceback (most recent call last):
  File "/opt/Training/python/automation_training/venv/lib/python3.8/site-packages/nornir/core/task.py", line 99, in start
    r = self.task(self, **self.params)
  File "/opt/Training/python/automation_training/venv/lib/python3.8/site-packages/nornir_scrapli/tasks/core/send_command.py", line 36, in send_command
    scrapli_conn = task.host.get_connection("scrapli", task.nornir.config)
  File "/opt/Training/python/automation_training/venv/lib/python3.8/site-packages/nornir/core/inventory.py", line 494, in get_connection
    self.open_connection(
  File "/opt/Training/python/automation_training/venv/lib/python3.8/site-packages/nornir/core/inventory.py", line 546, in open_connection
    conn_obj.open(
  File "/opt/Training/python/automation_training/venv/lib/python3.8/site-packages/nornir_scrapli/connection.py", line 105, in open
    connection.open()
  File "/opt/Training/python/automation_training/venv/lib/python3.8/site-packages/scrapli/driver/base/sync_driver.py", line 88, in open
    self.channel.channel_authenticate_ssh(
  File "/opt/Training/python/automation_training/venv/lib/python3.8/site-packages/scrapli/decorators.py", line 216, in decorate
    return _multiprocessing_timeout(
  File "/opt/Training/python/automation_training/venv/lib/python3.8/site-packages/scrapli/decorators.py", line 113, in _multiprocessing_timeout
    return future.result()
  File "/usr/lib/python3.8/concurrent/futures/_base.py", line 437, in result
    return self.__get_result()
  File "/usr/lib/python3.8/concurrent/futures/_base.py", line 389, in __get_result
    raise self._exception
  File "/usr/lib/python3.8/concurrent/futures/thread.py", line 57, in run
    result = self.fn(*self.args, **self.kwargs)
  File "/opt/Training/python/automation_training/venv/lib/python3.8/site-packages/scrapli/channel/sync_channel.py", line 290, in channel_authenticate_ssh
    self._ssh_message_handler(output=authenticate_buf)
  File "/opt/Training/python/automation_training/venv/lib/python3.8/site-packages/scrapli/channel/base_channel.py", line 432, in _ssh_message_handler
    raise ScrapliAuthenticationFailed(msg)
scrapli.exceptions.ScrapliAuthenticationFailed: b'\npermission denied, please try again.\n'

2022-10-21 10:00:45,346 - nornir.core.task -    ERROR -      start() - Host 'cart-colo': task 'credentials_test' failed with traceback:
Traceback (most recent call last):
  File "/opt/Training/python/automation_training/venv/lib/python3.8/site-packages/nornir/core/task.py", line 99, in start
    r = self.task(self, **self.params)
  File "script2.py", line 9, in credentials_test
    task.run(send_command, command="show ip int br")
  File "/opt/Training/python/automation_training/venv/lib/python3.8/site-packages/nornir/core/task.py", line 174, in run
    raise NornirSubTaskError(task=run_task, result=r)
nornir.core.exceptions.NornirSubTaskError: Subtask: send_command (failed)


2022-10-21 10:00:45,373 - nornir.core.task -    ERROR -      start() - Host 'ny5-feed-sw1b': task 'send_command' failed with traceback:
Traceback (most recent call last):
  File "/opt/Training/python/automation_training/venv/lib/python3.8/site-packages/nornir/core/task.py", line 99, in start
    r = self.task(self, **self.params)
  File "/opt/Training/python/automation_training/venv/lib/python3.8/site-packages/nornir_scrapli/tasks/core/send_command.py", line 36, in send_command
    scrapli_conn = task.host.get_connection("scrapli", task.nornir.config)
  File "/opt/Training/python/automation_training/venv/lib/python3.8/site-packages/nornir/core/inventory.py", line 494, in get_connection
    self.open_connection(
  File "/opt/Training/python/automation_training/venv/lib/python3.8/site-packages/nornir/core/inventory.py", line 546, in open_connection
    conn_obj.open(
  File "/opt/Training/python/automation_training/venv/lib/python3.8/site-packages/nornir_scrapli/connection.py", line 105, in open
    connection.open()
  File "/opt/Training/python/automation_training/venv/lib/python3.8/site-packages/scrapli/driver/base/sync_driver.py", line 88, in open
    self.channel.channel_authenticate_ssh(
  File "/opt/Training/python/automation_training/venv/lib/python3.8/site-packages/scrapli/decorators.py", line 216, in decorate
    return _multiprocessing_timeout(
  File "/opt/Training/python/automation_training/venv/lib/python3.8/site-packages/scrapli/decorators.py", line 113, in _multiprocessing_timeout
    return future.result()
  File "/usr/lib/python3.8/concurrent/futures/_base.py", line 437, in result
    return self.__get_result()
  File "/usr/lib/python3.8/concurrent/futures/_base.py", line 389, in __get_result
    raise self._exception
  File "/usr/lib/python3.8/concurrent/futures/thread.py", line 57, in run
    result = self.fn(*self.args, **self.kwargs)
  File "/opt/Training/python/automation_training/venv/lib/python3.8/site-packages/scrapli/channel/sync_channel.py", line 302, in channel_authenticate_ssh
    raise ScrapliAuthenticationFailed(msg)
scrapli.exceptions.ScrapliAuthenticationFailed: password prompt seen more than once, assuming auth failed

2022-10-21 10:00:45,374 - nornir.core.task -    ERROR -      start() - Host 'ny5-feed-sw1b': task 'credentials_test' failed with traceback:
Traceback (most recent call last):
  File "/opt/Training/python/automation_training/venv/lib/python3.8/site-packages/nornir/core/task.py", line 99, in start
    r = self.task(self, **self.params)
  File "script2.py", line 9, in credentials_test
    task.run(send_command, command="show ip int br")
  File "/opt/Training/python/automation_training/venv/lib/python3.8/site-packages/nornir/core/task.py", line 174, in run
    raise NornirSubTaskError(task=run_task, result=r)
nornir.core.exceptions.NornirSubTaskError: Subtask: send_command (failed)


2022-10-21 10:00:45,374 - nornir.core.task -    ERROR -      start() - Host 'ny5-feed-sw1a': task 'send_command' failed with traceback:
Traceback (most recent call last):
  File "/opt/Training/python/automation_training/venv/lib/python3.8/site-packages/nornir/core/task.py", line 99, in start
    r = self.task(self, **self.params)
  File "/opt/Training/python/automation_training/venv/lib/python3.8/site-packages/nornir_scrapli/tasks/core/send_command.py", line 36, in send_command
    scrapli_conn = task.host.get_connection("scrapli", task.nornir.config)
  File "/opt/Training/python/automation_training/venv/lib/python3.8/site-packages/nornir/core/inventory.py", line 494, in get_connection
    self.open_connection(
  File "/opt/Training/python/automation_training/venv/lib/python3.8/site-packages/nornir/core/inventory.py", line 546, in open_connection
    conn_obj.open(
  File "/opt/Training/python/automation_training/venv/lib/python3.8/site-packages/nornir_scrapli/connection.py", line 105, in open
    connection.open()
  File "/opt/Training/python/automation_training/venv/lib/python3.8/site-packages/scrapli/driver/base/sync_driver.py", line 88, in open
    self.channel.channel_authenticate_ssh(
  File "/opt/Training/python/automation_training/venv/lib/python3.8/site-packages/scrapli/decorators.py", line 216, in decorate
    return _multiprocessing_timeout(
  File "/opt/Training/python/automation_training/venv/lib/python3.8/site-packages/scrapli/decorators.py", line 113, in _multiprocessing_timeout
    return future.result()
  File "/usr/lib/python3.8/concurrent/futures/_base.py", line 437, in result
    return self.__get_result()
  File "/usr/lib/python3.8/concurrent/futures/_base.py", line 389, in __get_result
    raise self._exception
  File "/usr/lib/python3.8/concurrent/futures/thread.py", line 57, in run
    result = self.fn(*self.args, **self.kwargs)
  File "/opt/Training/python/automation_training/venv/lib/python3.8/site-packages/scrapli/channel/sync_channel.py", line 302, in channel_authenticate_ssh
    raise ScrapliAuthenticationFailed(msg)
scrapli.exceptions.ScrapliAuthenticationFailed: password prompt seen more than once, assuming auth failed

2022-10-21 10:00:45,374 - nornir.core.task -    ERROR -      start() - Host 'ny5-feed-sw1a': task 'credentials_test' failed with traceback:
Traceback (most recent call last):
  File "/opt/Training/python/automation_training/venv/lib/python3.8/site-packages/nornir/core/task.py", line 99, in start
    r = self.task(self, **self.params)
  File "script2.py", line 9, in credentials_test
    task.run(send_command, command="show ip int br")
  File "/opt/Training/python/automation_training/venv/lib/python3.8/site-packages/nornir/core/task.py", line 174, in run
    raise NornirSubTaskError(task=run_task, result=r)
nornir.core.exceptions.NornirSubTaskError: Subtask: send_command (failed)


2022-10-21 10:00:45,374 - nornir.core.task -    ERROR -      start() - Host 'telx-colo': task 'send_command' failed with traceback:
Traceback (most recent call last):
  File "/opt/Training/python/automation_training/venv/lib/python3.8/site-packages/nornir/core/task.py", line 99, in start
    r = self.task(self, **self.params)
  File "/opt/Training/python/automation_training/venv/lib/python3.8/site-packages/nornir_scrapli/tasks/core/send_command.py", line 36, in send_command
    scrapli_conn = task.host.get_connection("scrapli", task.nornir.config)
  File "/opt/Training/python/automation_training/venv/lib/python3.8/site-packages/nornir/core/inventory.py", line 494, in get_connection
    self.open_connection(
  File "/opt/Training/python/automation_training/venv/lib/python3.8/site-packages/nornir/core/inventory.py", line 546, in open_connection
    conn_obj.open(
  File "/opt/Training/python/automation_training/venv/lib/python3.8/site-packages/nornir_scrapli/connection.py", line 105, in open
    connection.open()
  File "/opt/Training/python/automation_training/venv/lib/python3.8/site-packages/scrapli/driver/base/sync_driver.py", line 88, in open
    self.channel.channel_authenticate_ssh(
  File "/opt/Training/python/automation_training/venv/lib/python3.8/site-packages/scrapli/decorators.py", line 216, in decorate
    return _multiprocessing_timeout(
  File "/opt/Training/python/automation_training/venv/lib/python3.8/site-packages/scrapli/decorators.py", line 113, in _multiprocessing_timeout
    return future.result()
  File "/usr/lib/python3.8/concurrent/futures/_base.py", line 437, in result
    return self.__get_result()
  File "/usr/lib/python3.8/concurrent/futures/_base.py", line 389, in __get_result
    raise self._exception
  File "/usr/lib/python3.8/concurrent/futures/thread.py", line 57, in run
    result = self.fn(*self.args, **self.kwargs)
  File "/opt/Training/python/automation_training/venv/lib/python3.8/site-packages/scrapli/channel/sync_channel.py", line 302, in channel_authenticate_ssh
    raise ScrapliAuthenticationFailed(msg)
scrapli.exceptions.ScrapliAuthenticationFailed: password prompt seen more than once, assuming auth failed

2022-10-21 10:00:45,375 - nornir.core.task -    ERROR -      start() - Host 'telx-colo': task 'credentials_test' failed with traceback:
Traceback (most recent call last):
  File "/opt/Training/python/automation_training/venv/lib/python3.8/site-packages/nornir/core/task.py", line 99, in start
    r = self.task(self, **self.params)
  File "script2.py", line 9, in credentials_test
    task.run(send_command, command="show ip int br")
  File "/opt/Training/python/automation_training/venv/lib/python3.8/site-packages/nornir/core/task.py", line 174, in run
    raise NornirSubTaskError(task=run_task, result=r)
nornir.core.exceptions.NornirSubTaskError: Subtask: send_command (failed)


2022-10-21 10:00:45,375 - nornir.core.task -    ERROR -      start() - Host 'ny5-feed-sw2': task 'send_command' failed with traceback:
Traceback (most recent call last):
  File "/opt/Training/python/automation_training/venv/lib/python3.8/site-packages/nornir/core/task.py", line 99, in start
    r = self.task(self, **self.params)
  File "/opt/Training/python/automation_training/venv/lib/python3.8/site-packages/nornir_scrapli/tasks/core/send_command.py", line 36, in send_command
    scrapli_conn = task.host.get_connection("scrapli", task.nornir.config)
  File "/opt/Training/python/automation_training/venv/lib/python3.8/site-packages/nornir/core/inventory.py", line 494, in get_connection
    self.open_connection(
  File "/opt/Training/python/automation_training/venv/lib/python3.8/site-packages/nornir/core/inventory.py", line 546, in open_connection
    conn_obj.open(
  File "/opt/Training/python/automation_training/venv/lib/python3.8/site-packages/nornir_scrapli/connection.py", line 105, in open
    connection.open()
  File "/opt/Training/python/automation_training/venv/lib/python3.8/site-packages/scrapli/driver/base/sync_driver.py", line 88, in open
    self.channel.channel_authenticate_ssh(
  File "/opt/Training/python/automation_training/venv/lib/python3.8/site-packages/scrapli/decorators.py", line 216, in decorate
    return _multiprocessing_timeout(
  File "/opt/Training/python/automation_training/venv/lib/python3.8/site-packages/scrapli/decorators.py", line 113, in _multiprocessing_timeout
    return future.result()
  File "/usr/lib/python3.8/concurrent/futures/_base.py", line 437, in result
    return self.__get_result()
  File "/usr/lib/python3.8/concurrent/futures/_base.py", line 389, in __get_result
    raise self._exception
  File "/usr/lib/python3.8/concurrent/futures/thread.py", line 57, in run
    result = self.fn(*self.args, **self.kwargs)
  File "/opt/Training/python/automation_training/venv/lib/python3.8/site-packages/scrapli/channel/sync_channel.py", line 302, in channel_authenticate_ssh
    raise ScrapliAuthenticationFailed(msg)
scrapli.exceptions.ScrapliAuthenticationFailed: password prompt seen more than once, assuming auth failed

2022-10-21 10:00:45,375 - nornir.core.task -    ERROR -      start() - Host 'ny5-feed-sw2': task 'credentials_test' failed with traceback:
Traceback (most recent call last):
  File "/opt/Training/python/automation_training/venv/lib/python3.8/site-packages/nornir/core/task.py", line 99, in start
    r = self.task(self, **self.params)
  File "script2.py", line 9, in credentials_test
    task.run(send_command, command="show ip int br")
  File "/opt/Training/python/automation_training/venv/lib/python3.8/site-packages/nornir/core/task.py", line 174, in run
    raise NornirSubTaskError(task=run_task, result=r)
nornir.core.exceptions.NornirSubTaskError: Subtask: send_command (failed)


2022-10-21 10:00:45,385 - nornir.core.task -    ERROR -      start() - Host 'ny5-feed-sw3': task 'send_command' failed with traceback:
Traceback (most recent call last):
  File "/opt/Training/python/automation_training/venv/lib/python3.8/site-packages/nornir/core/task.py", line 99, in start
    r = self.task(self, **self.params)
  File "/opt/Training/python/automation_training/venv/lib/python3.8/site-packages/nornir_scrapli/tasks/core/send_command.py", line 36, in send_command
    scrapli_conn = task.host.get_connection("scrapli", task.nornir.config)
  File "/opt/Training/python/automation_training/venv/lib/python3.8/site-packages/nornir/core/inventory.py", line 494, in get_connection
    self.open_connection(
  File "/opt/Training/python/automation_training/venv/lib/python3.8/site-packages/nornir/core/inventory.py", line 546, in open_connection
    conn_obj.open(
  File "/opt/Training/python/automation_training/venv/lib/python3.8/site-packages/nornir_scrapli/connection.py", line 105, in open
    connection.open()
  File "/opt/Training/python/automation_training/venv/lib/python3.8/site-packages/scrapli/driver/base/sync_driver.py", line 88, in open
    self.channel.channel_authenticate_ssh(
  File "/opt/Training/python/automation_training/venv/lib/python3.8/site-packages/scrapli/decorators.py", line 216, in decorate
    return _multiprocessing_timeout(
  File "/opt/Training/python/automation_training/venv/lib/python3.8/site-packages/scrapli/decorators.py", line 113, in _multiprocessing_timeout
    return future.result()
  File "/usr/lib/python3.8/concurrent/futures/_base.py", line 437, in result
    return self.__get_result()
  File "/usr/lib/python3.8/concurrent/futures/_base.py", line 389, in __get_result
    raise self._exception
  File "/usr/lib/python3.8/concurrent/futures/thread.py", line 57, in run
    result = self.fn(*self.args, **self.kwargs)
  File "/opt/Training/python/automation_training/venv/lib/python3.8/site-packages/scrapli/channel/sync_channel.py", line 302, in channel_authenticate_ssh
    raise ScrapliAuthenticationFailed(msg)
scrapli.exceptions.ScrapliAuthenticationFailed: password prompt seen more than once, assuming auth failed

2022-10-21 10:00:45,385 - nornir.core.task -    ERROR -      start() - Host 'ny5-feed-sw3': task 'credentials_test' failed with traceback:
Traceback (most recent call last):
  File "/opt/Training/python/automation_training/venv/lib/python3.8/site-packages/nornir/core/task.py", line 99, in start
    r = self.task(self, **self.params)
  File "script2.py", line 9, in credentials_test
    task.run(send_command, command="show ip int br")
  File "/opt/Training/python/automation_training/venv/lib/python3.8/site-packages/nornir/core/task.py", line 174, in run
    raise NornirSubTaskError(task=run_task, result=r)
nornir.core.exceptions.NornirSubTaskError: Subtask: send_command (failed)


2022-10-21 10:04:35,371 -  nornir.core -     INFO -        run() - Running task 'credentials_test' with args {} on 6 hosts
2022-10-21 10:34:31,076 -  nornir.core -     INFO -        run() - Running task 'credentials_test' with args {} on 6 hosts
2022-10-21 10:37:45,552 -  nornir.core -     INFO -        run() - Running task 'credentials_test' with args {} on 6 hosts
2022-10-21 10:38:06,286 -  nornir.core -     INFO -        run() - Running task 'credentials_test' with args {} on 6 hosts
2022-10-21 10:38:10,245 - nornir.core.task -    ERROR -      start() - Host 'telx-colo': task 'send_command' failed with traceback:
Traceback (most recent call last):
  File "/opt/Training/python/automation_training/venv/lib/python3.8/site-packages/nornir/core/task.py", line 99, in start
    r = self.task(self, **self.params)
  File "/opt/Training/python/automation_training/venv/lib/python3.8/site-packages/nornir_scrapli/tasks/core/send_command.py", line 36, in send_command
    scrapli_conn = task.host.get_connection("scrapli", task.nornir.config)
  File "/opt/Training/python/automation_training/venv/lib/python3.8/site-packages/nornir/core/inventory.py", line 494, in get_connection
    self.open_connection(
  File "/opt/Training/python/automation_training/venv/lib/python3.8/site-packages/nornir/core/inventory.py", line 546, in open_connection
    conn_obj.open(
  File "/opt/Training/python/automation_training/venv/lib/python3.8/site-packages/nornir_scrapli/connection.py", line 105, in open
    connection.open()
  File "/opt/Training/python/automation_training/venv/lib/python3.8/site-packages/scrapli/driver/base/sync_driver.py", line 88, in open
    self.channel.channel_authenticate_ssh(
  File "/opt/Training/python/automation_training/venv/lib/python3.8/site-packages/scrapli/decorators.py", line 216, in decorate
    return _multiprocessing_timeout(
  File "/opt/Training/python/automation_training/venv/lib/python3.8/site-packages/scrapli/decorators.py", line 113, in _multiprocessing_timeout
    return future.result()
  File "/usr/lib/python3.8/concurrent/futures/_base.py", line 437, in result
    return self.__get_result()
  File "/usr/lib/python3.8/concurrent/futures/_base.py", line 389, in __get_result
    raise self._exception
  File "/usr/lib/python3.8/concurrent/futures/thread.py", line 57, in run
    result = self.fn(*self.args, **self.kwargs)
  File "/opt/Training/python/automation_training/venv/lib/python3.8/site-packages/scrapli/channel/sync_channel.py", line 302, in channel_authenticate_ssh
    raise ScrapliAuthenticationFailed(msg)
scrapli.exceptions.ScrapliAuthenticationFailed: password prompt seen more than once, assuming auth failed

2022-10-21 10:38:10,245 - nornir.core.task -    ERROR -      start() - Host 'telx-colo': task 'credentials_test' failed with traceback:
Traceback (most recent call last):
  File "/opt/Training/python/automation_training/venv/lib/python3.8/site-packages/nornir/core/task.py", line 99, in start
    r = self.task(self, **self.params)
  File "pass_arguments_into_scripts.py", line 25, in credentials_test
    task.run(send_command, command="show ip int br")
  File "/opt/Training/python/automation_training/venv/lib/python3.8/site-packages/nornir/core/task.py", line 174, in run
    raise NornirSubTaskError(task=run_task, result=r)
nornir.core.exceptions.NornirSubTaskError: Subtask: send_command (failed)


2022-10-21 10:42:51,771 -  nornir.core -     INFO -        run() - Running task 'credentials_test' with args {} on 6 hosts
2022-10-21 11:37:48,767 -  nornir.core -     INFO -        run() - Running task 'credentials_test' with args {} on 6 hosts
2022-10-21 11:37:49,186 - nornir.core.task -    ERROR -      start() - Host 'telx-colo': task 'send_command' failed with traceback:
Traceback (most recent call last):
  File "/opt/Training/python/automation_training/venv/lib/python3.8/site-packages/nornir/core/task.py", line 99, in start
    r = self.task(self, **self.params)
  File "/opt/Training/python/automation_training/venv/lib/python3.8/site-packages/nornir_scrapli/tasks/core/send_command.py", line 36, in send_command
    scrapli_conn = task.host.get_connection("scrapli", task.nornir.config)
  File "/opt/Training/python/automation_training/venv/lib/python3.8/site-packages/nornir/core/inventory.py", line 494, in get_connection
    self.open_connection(
  File "/opt/Training/python/automation_training/venv/lib/python3.8/site-packages/nornir/core/inventory.py", line 546, in open_connection
    conn_obj.open(
  File "/opt/Training/python/automation_training/venv/lib/python3.8/site-packages/nornir_scrapli/connection.py", line 105, in open
    connection.open()
  File "/opt/Training/python/automation_training/venv/lib/python3.8/site-packages/scrapli/driver/base/sync_driver.py", line 88, in open
    self.channel.channel_authenticate_ssh(
  File "/opt/Training/python/automation_training/venv/lib/python3.8/site-packages/scrapli/decorators.py", line 216, in decorate
    return _multiprocessing_timeout(
  File "/opt/Training/python/automation_training/venv/lib/python3.8/site-packages/scrapli/decorators.py", line 113, in _multiprocessing_timeout
    return future.result()
  File "/usr/lib/python3.8/concurrent/futures/_base.py", line 437, in result
    return self.__get_result()
  File "/usr/lib/python3.8/concurrent/futures/_base.py", line 389, in __get_result
    raise self._exception
  File "/usr/lib/python3.8/concurrent/futures/thread.py", line 57, in run
    result = self.fn(*self.args, **self.kwargs)
  File "/opt/Training/python/automation_training/venv/lib/python3.8/site-packages/scrapli/channel/sync_channel.py", line 302, in channel_authenticate_ssh
    raise ScrapliAuthenticationFailed(msg)
scrapli.exceptions.ScrapliAuthenticationFailed: password prompt seen more than once, assuming auth failed

2022-10-21 11:37:49,186 - nornir.core.task -    ERROR -      start() - Host 'telx-colo': task 'credentials_test' failed with traceback:
Traceback (most recent call last):
  File "/opt/Training/python/automation_training/venv/lib/python3.8/site-packages/nornir/core/task.py", line 99, in start
    r = self.task(self, **self.params)
  File "environment_variables.py", line 14, in credentials_test
    task.run(send_command, command="show ip int br")
  File "/opt/Training/python/automation_training/venv/lib/python3.8/site-packages/nornir/core/task.py", line 174, in run
    raise NornirSubTaskError(task=run_task, result=r)
nornir.core.exceptions.NornirSubTaskError: Subtask: send_command (failed)


2022-10-21 11:38:47,650 -  nornir.core -     INFO -        run() - Running task 'credentials_test' with args {} on 6 hosts
2022-10-21 11:41:36,482 -  nornir.core -     INFO -        run() - Running task 'credentials_test' with args {} on 6 hosts
2022-10-21 12:46:02,295 -  nornir.core -     INFO -        run() - Running task 'credentials_test' with args {} on 6 hosts
2022-10-21 12:47:52,579 -  nornir.core -     INFO -        run() - Running task 'credentials_test' with args {} on 6 hosts
