2022-10-21 13:26:43,686 -  nornir.core -     INFO -        run() - Running task 'pull_structured_data' with args {} on 6 hosts
2022-10-21 13:26:43,995 - nornir.core.task -    ERROR -      start() - Host 'cart-colo': task 'send_command' failed with traceback:
Traceback (most recent call last):
  File "/opt/Training/python/automation_training/venv/lib/python3.8/site-packages/nornir/core/task.py", line 99, in start
    r = self.task(self, **self.params)
  File "/opt/Training/python/automation_training/venv/lib/python3.8/site-packages/nornir_scrapli/tasks/core/send_command.py", line 36, in send_command
    scrapli_conn = task.host.get_connection("scrapli", task.nornir.config)
  File "/opt/Training/python/automation_training/venv/lib/python3.8/site-packages/nornir/core/inventory.py", line 494, in get_connection
    self.open_connection(
  File "/opt/Training/python/automation_training/venv/lib/python3.8/site-packages/nornir/core/inventory.py", line 546, in open_connection
    conn_obj.open(
  File "/opt/Training/python/automation_training/venv/lib/python3.8/site-packages/nornir_scrapli/connection.py", line 105, in open
    connection.open()
  File "/opt/Training/python/automation_training/venv/lib/python3.8/site-packages/scrapli/driver/base/sync_driver.py", line 88, in open
    self.channel.channel_authenticate_ssh(
  File "/opt/Training/python/automation_training/venv/lib/python3.8/site-packages/scrapli/decorators.py", line 216, in decorate
    return _multiprocessing_timeout(
  File "/opt/Training/python/automation_training/venv/lib/python3.8/site-packages/scrapli/decorators.py", line 113, in _multiprocessing_timeout
    return future.result()
  File "/usr/lib/python3.8/concurrent/futures/_base.py", line 437, in result
    return self.__get_result()
  File "/usr/lib/python3.8/concurrent/futures/_base.py", line 389, in __get_result
    raise self._exception
  File "/usr/lib/python3.8/concurrent/futures/thread.py", line 57, in run
    result = self.fn(*self.args, **self.kwargs)
  File "/opt/Training/python/automation_training/venv/lib/python3.8/site-packages/scrapli/channel/sync_channel.py", line 290, in channel_authenticate_ssh
    self._ssh_message_handler(output=authenticate_buf)
  File "/opt/Training/python/automation_training/venv/lib/python3.8/site-packages/scrapli/channel/base_channel.py", line 432, in _ssh_message_handler
    raise ScrapliAuthenticationFailed(msg)
scrapli.exceptions.ScrapliAuthenticationFailed: b'\npermission denied, please try again.\n'

2022-10-21 13:26:43,995 - nornir.core.task -    ERROR -      start() - Host 'cart-colo': task 'pull_structured_data' failed with traceback:
Traceback (most recent call last):
  File "/opt/Training/python/automation_training/venv/lib/python3.8/site-packages/nornir/core/task.py", line 99, in start
    r = self.task(self, **self.params)
  File "script1.py", line 9, in pull_structured_data
    task.run(task=send_command, command="show ver")
  File "/opt/Training/python/automation_training/venv/lib/python3.8/site-packages/nornir/core/task.py", line 174, in run
    raise NornirSubTaskError(task=run_task, result=r)
nornir.core.exceptions.NornirSubTaskError: Subtask: send_command (failed)


2022-10-21 13:26:44,072 - nornir.core.task -    ERROR -      start() - Host 'ny5-feed-sw3': task 'send_command' failed with traceback:
Traceback (most recent call last):
  File "/opt/Training/python/automation_training/venv/lib/python3.8/site-packages/nornir/core/task.py", line 99, in start
    r = self.task(self, **self.params)
  File "/opt/Training/python/automation_training/venv/lib/python3.8/site-packages/nornir_scrapli/tasks/core/send_command.py", line 36, in send_command
    scrapli_conn = task.host.get_connection("scrapli", task.nornir.config)
  File "/opt/Training/python/automation_training/venv/lib/python3.8/site-packages/nornir/core/inventory.py", line 494, in get_connection
    self.open_connection(
  File "/opt/Training/python/automation_training/venv/lib/python3.8/site-packages/nornir/core/inventory.py", line 546, in open_connection
    conn_obj.open(
  File "/opt/Training/python/automation_training/venv/lib/python3.8/site-packages/nornir_scrapli/connection.py", line 105, in open
    connection.open()
  File "/opt/Training/python/automation_training/venv/lib/python3.8/site-packages/scrapli/driver/base/sync_driver.py", line 88, in open
    self.channel.channel_authenticate_ssh(
  File "/opt/Training/python/automation_training/venv/lib/python3.8/site-packages/scrapli/decorators.py", line 216, in decorate
    return _multiprocessing_timeout(
  File "/opt/Training/python/automation_training/venv/lib/python3.8/site-packages/scrapli/decorators.py", line 113, in _multiprocessing_timeout
    return future.result()
  File "/usr/lib/python3.8/concurrent/futures/_base.py", line 437, in result
    return self.__get_result()
  File "/usr/lib/python3.8/concurrent/futures/_base.py", line 389, in __get_result
    raise self._exception
  File "/usr/lib/python3.8/concurrent/futures/thread.py", line 57, in run
    result = self.fn(*self.args, **self.kwargs)
  File "/opt/Training/python/automation_training/venv/lib/python3.8/site-packages/scrapli/channel/sync_channel.py", line 302, in channel_authenticate_ssh
    raise ScrapliAuthenticationFailed(msg)
scrapli.exceptions.ScrapliAuthenticationFailed: password prompt seen more than once, assuming auth failed

2022-10-21 13:26:44,073 - nornir.core.task -    ERROR -      start() - Host 'ny5-feed-sw3': task 'pull_structured_data' failed with traceback:
Traceback (most recent call last):
  File "/opt/Training/python/automation_training/venv/lib/python3.8/site-packages/nornir/core/task.py", line 99, in start
    r = self.task(self, **self.params)
  File "script1.py", line 9, in pull_structured_data
    task.run(task=send_command, command="show ver")
  File "/opt/Training/python/automation_training/venv/lib/python3.8/site-packages/nornir/core/task.py", line 174, in run
    raise NornirSubTaskError(task=run_task, result=r)
nornir.core.exceptions.NornirSubTaskError: Subtask: send_command (failed)


2022-10-21 13:26:44,082 - nornir.core.task -    ERROR -      start() - Host 'ny5-feed-sw2': task 'send_command' failed with traceback:
Traceback (most recent call last):
  File "/opt/Training/python/automation_training/venv/lib/python3.8/site-packages/nornir/core/task.py", line 99, in start
    r = self.task(self, **self.params)
  File "/opt/Training/python/automation_training/venv/lib/python3.8/site-packages/nornir_scrapli/tasks/core/send_command.py", line 36, in send_command
    scrapli_conn = task.host.get_connection("scrapli", task.nornir.config)
  File "/opt/Training/python/automation_training/venv/lib/python3.8/site-packages/nornir/core/inventory.py", line 494, in get_connection
    self.open_connection(
  File "/opt/Training/python/automation_training/venv/lib/python3.8/site-packages/nornir/core/inventory.py", line 546, in open_connection
    conn_obj.open(
  File "/opt/Training/python/automation_training/venv/lib/python3.8/site-packages/nornir_scrapli/connection.py", line 105, in open
    connection.open()
  File "/opt/Training/python/automation_training/venv/lib/python3.8/site-packages/scrapli/driver/base/sync_driver.py", line 88, in open
    self.channel.channel_authenticate_ssh(
  File "/opt/Training/python/automation_training/venv/lib/python3.8/site-packages/scrapli/decorators.py", line 216, in decorate
    return _multiprocessing_timeout(
  File "/opt/Training/python/automation_training/venv/lib/python3.8/site-packages/scrapli/decorators.py", line 113, in _multiprocessing_timeout
    return future.result()
  File "/usr/lib/python3.8/concurrent/futures/_base.py", line 437, in result
    return self.__get_result()
  File "/usr/lib/python3.8/concurrent/futures/_base.py", line 389, in __get_result
    raise self._exception
  File "/usr/lib/python3.8/concurrent/futures/thread.py", line 57, in run
    result = self.fn(*self.args, **self.kwargs)
  File "/opt/Training/python/automation_training/venv/lib/python3.8/site-packages/scrapli/channel/sync_channel.py", line 302, in channel_authenticate_ssh
    raise ScrapliAuthenticationFailed(msg)
scrapli.exceptions.ScrapliAuthenticationFailed: password prompt seen more than once, assuming auth failed

2022-10-21 13:26:44,082 - nornir.core.task -    ERROR -      start() - Host 'ny5-feed-sw2': task 'pull_structured_data' failed with traceback:
Traceback (most recent call last):
  File "/opt/Training/python/automation_training/venv/lib/python3.8/site-packages/nornir/core/task.py", line 99, in start
    r = self.task(self, **self.params)
  File "script1.py", line 9, in pull_structured_data
    task.run(task=send_command, command="show ver")
  File "/opt/Training/python/automation_training/venv/lib/python3.8/site-packages/nornir/core/task.py", line 174, in run
    raise NornirSubTaskError(task=run_task, result=r)
nornir.core.exceptions.NornirSubTaskError: Subtask: send_command (failed)


2022-10-21 13:26:44,093 - nornir.core.task -    ERROR -      start() - Host 'ny5-feed-sw1a': task 'send_command' failed with traceback:
Traceback (most recent call last):
  File "/opt/Training/python/automation_training/venv/lib/python3.8/site-packages/nornir/core/task.py", line 99, in start
    r = self.task(self, **self.params)
  File "/opt/Training/python/automation_training/venv/lib/python3.8/site-packages/nornir_scrapli/tasks/core/send_command.py", line 36, in send_command
    scrapli_conn = task.host.get_connection("scrapli", task.nornir.config)
  File "/opt/Training/python/automation_training/venv/lib/python3.8/site-packages/nornir/core/inventory.py", line 494, in get_connection
    self.open_connection(
  File "/opt/Training/python/automation_training/venv/lib/python3.8/site-packages/nornir/core/inventory.py", line 546, in open_connection
    conn_obj.open(
  File "/opt/Training/python/automation_training/venv/lib/python3.8/site-packages/nornir_scrapli/connection.py", line 105, in open
    connection.open()
  File "/opt/Training/python/automation_training/venv/lib/python3.8/site-packages/scrapli/driver/base/sync_driver.py", line 88, in open
    self.channel.channel_authenticate_ssh(
  File "/opt/Training/python/automation_training/venv/lib/python3.8/site-packages/scrapli/decorators.py", line 216, in decorate
    return _multiprocessing_timeout(
  File "/opt/Training/python/automation_training/venv/lib/python3.8/site-packages/scrapli/decorators.py", line 113, in _multiprocessing_timeout
    return future.result()
  File "/usr/lib/python3.8/concurrent/futures/_base.py", line 437, in result
    return self.__get_result()
  File "/usr/lib/python3.8/concurrent/futures/_base.py", line 389, in __get_result
    raise self._exception
  File "/usr/lib/python3.8/concurrent/futures/thread.py", line 57, in run
    result = self.fn(*self.args, **self.kwargs)
  File "/opt/Training/python/automation_training/venv/lib/python3.8/site-packages/scrapli/channel/sync_channel.py", line 302, in channel_authenticate_ssh
    raise ScrapliAuthenticationFailed(msg)
scrapli.exceptions.ScrapliAuthenticationFailed: password prompt seen more than once, assuming auth failed

2022-10-21 13:26:44,093 - nornir.core.task -    ERROR -      start() - Host 'ny5-feed-sw1a': task 'pull_structured_data' failed with traceback:
Traceback (most recent call last):
  File "/opt/Training/python/automation_training/venv/lib/python3.8/site-packages/nornir/core/task.py", line 99, in start
    r = self.task(self, **self.params)
  File "script1.py", line 9, in pull_structured_data
    task.run(task=send_command, command="show ver")
  File "/opt/Training/python/automation_training/venv/lib/python3.8/site-packages/nornir/core/task.py", line 174, in run
    raise NornirSubTaskError(task=run_task, result=r)
nornir.core.exceptions.NornirSubTaskError: Subtask: send_command (failed)


2022-10-21 13:26:44,213 - nornir.core.task -    ERROR -      start() - Host 'ny5-feed-sw1b': task 'send_command' failed with traceback:
Traceback (most recent call last):
  File "/opt/Training/python/automation_training/venv/lib/python3.8/site-packages/nornir/core/task.py", line 99, in start
    r = self.task(self, **self.params)
  File "/opt/Training/python/automation_training/venv/lib/python3.8/site-packages/nornir_scrapli/tasks/core/send_command.py", line 36, in send_command
    scrapli_conn = task.host.get_connection("scrapli", task.nornir.config)
  File "/opt/Training/python/automation_training/venv/lib/python3.8/site-packages/nornir/core/inventory.py", line 494, in get_connection
    self.open_connection(
  File "/opt/Training/python/automation_training/venv/lib/python3.8/site-packages/nornir/core/inventory.py", line 546, in open_connection
    conn_obj.open(
  File "/opt/Training/python/automation_training/venv/lib/python3.8/site-packages/nornir_scrapli/connection.py", line 105, in open
    connection.open()
  File "/opt/Training/python/automation_training/venv/lib/python3.8/site-packages/scrapli/driver/base/sync_driver.py", line 88, in open
    self.channel.channel_authenticate_ssh(
  File "/opt/Training/python/automation_training/venv/lib/python3.8/site-packages/scrapli/decorators.py", line 216, in decorate
    return _multiprocessing_timeout(
  File "/opt/Training/python/automation_training/venv/lib/python3.8/site-packages/scrapli/decorators.py", line 113, in _multiprocessing_timeout
    return future.result()
  File "/usr/lib/python3.8/concurrent/futures/_base.py", line 437, in result
    return self.__get_result()
  File "/usr/lib/python3.8/concurrent/futures/_base.py", line 389, in __get_result
    raise self._exception
  File "/usr/lib/python3.8/concurrent/futures/thread.py", line 57, in run
    result = self.fn(*self.args, **self.kwargs)
  File "/opt/Training/python/automation_training/venv/lib/python3.8/site-packages/scrapli/channel/sync_channel.py", line 302, in channel_authenticate_ssh
    raise ScrapliAuthenticationFailed(msg)
scrapli.exceptions.ScrapliAuthenticationFailed: password prompt seen more than once, assuming auth failed

2022-10-21 13:26:44,213 - nornir.core.task -    ERROR -      start() - Host 'ny5-feed-sw1b': task 'pull_structured_data' failed with traceback:
Traceback (most recent call last):
  File "/opt/Training/python/automation_training/venv/lib/python3.8/site-packages/nornir/core/task.py", line 99, in start
    r = self.task(self, **self.params)
  File "script1.py", line 9, in pull_structured_data
    task.run(task=send_command, command="show ver")
  File "/opt/Training/python/automation_training/venv/lib/python3.8/site-packages/nornir/core/task.py", line 174, in run
    raise NornirSubTaskError(task=run_task, result=r)
nornir.core.exceptions.NornirSubTaskError: Subtask: send_command (failed)


2022-10-21 13:26:44,218 - nornir.core.task -    ERROR -      start() - Host 'telx-colo': task 'send_command' failed with traceback:
Traceback (most recent call last):
  File "/opt/Training/python/automation_training/venv/lib/python3.8/site-packages/nornir/core/task.py", line 99, in start
    r = self.task(self, **self.params)
  File "/opt/Training/python/automation_training/venv/lib/python3.8/site-packages/nornir_scrapli/tasks/core/send_command.py", line 36, in send_command
    scrapli_conn = task.host.get_connection("scrapli", task.nornir.config)
  File "/opt/Training/python/automation_training/venv/lib/python3.8/site-packages/nornir/core/inventory.py", line 494, in get_connection
    self.open_connection(
  File "/opt/Training/python/automation_training/venv/lib/python3.8/site-packages/nornir/core/inventory.py", line 546, in open_connection
    conn_obj.open(
  File "/opt/Training/python/automation_training/venv/lib/python3.8/site-packages/nornir_scrapli/connection.py", line 105, in open
    connection.open()
  File "/opt/Training/python/automation_training/venv/lib/python3.8/site-packages/scrapli/driver/base/sync_driver.py", line 88, in open
    self.channel.channel_authenticate_ssh(
  File "/opt/Training/python/automation_training/venv/lib/python3.8/site-packages/scrapli/decorators.py", line 216, in decorate
    return _multiprocessing_timeout(
  File "/opt/Training/python/automation_training/venv/lib/python3.8/site-packages/scrapli/decorators.py", line 113, in _multiprocessing_timeout
    return future.result()
  File "/usr/lib/python3.8/concurrent/futures/_base.py", line 437, in result
    return self.__get_result()
  File "/usr/lib/python3.8/concurrent/futures/_base.py", line 389, in __get_result
    raise self._exception
  File "/usr/lib/python3.8/concurrent/futures/thread.py", line 57, in run
    result = self.fn(*self.args, **self.kwargs)
  File "/opt/Training/python/automation_training/venv/lib/python3.8/site-packages/scrapli/channel/sync_channel.py", line 302, in channel_authenticate_ssh
    raise ScrapliAuthenticationFailed(msg)
scrapli.exceptions.ScrapliAuthenticationFailed: password prompt seen more than once, assuming auth failed

2022-10-21 13:26:44,218 - nornir.core.task -    ERROR -      start() - Host 'telx-colo': task 'pull_structured_data' failed with traceback:
Traceback (most recent call last):
  File "/opt/Training/python/automation_training/venv/lib/python3.8/site-packages/nornir/core/task.py", line 99, in start
    r = self.task(self, **self.params)
  File "script1.py", line 9, in pull_structured_data
    task.run(task=send_command, command="show ver")
  File "/opt/Training/python/automation_training/venv/lib/python3.8/site-packages/nornir/core/task.py", line 174, in run
    raise NornirSubTaskError(task=run_task, result=r)
nornir.core.exceptions.NornirSubTaskError: Subtask: send_command (failed)


2022-10-21 13:27:23,140 -  nornir.core -     INFO -        run() - Running task 'pull_structured_data' with args {} on 6 hosts
2022-10-21 13:31:07,562 -  nornir.core -     INFO -        run() - Running task 'pull_structured_data' with args {} on 6 hosts
2022-10-21 13:31:32,314 -  nornir.core -     INFO -        run() - Running task 'pull_structured_data' with args {} on 6 hosts
2022-10-21 13:40:57,047 -  nornir.core -     INFO -        run() - Running task 'pull_structured_data' with args {} on 6 hosts
2022-10-21 13:57:38,811 -  nornir.core -     INFO -        run() - Running task 'pull_structured_data' with args {} on 6 hosts
2022-10-21 14:08:03,964 -  nornir.core -     INFO -        run() - Running task 'pull_structured_data' with args {} on 6 hosts
2022-10-21 14:13:51,846 -  nornir.core -     INFO -        run() - Running task 'pull_structured_data' with args {} on 6 hosts
2022-10-21 14:15:17,815 -  nornir.core -     INFO -        run() - Running task 'pull_structured_data' with args {} on 6 hosts
2022-10-21 14:17:27,541 -  nornir.core -     INFO -        run() - Running task 'pull_structured_data' with args {} on 6 hosts
2022-10-21 14:47:42,326 -  nornir.core -     INFO -        run() - Running task 'pull_structured_data' with args {} on 6 hosts
2022-10-21 15:18:24,525 -  nornir.core -     INFO -        run() - Running task 'pull_structured_data' with args {} on 1 hosts
2022-10-21 15:18:54,808 - nornir.core.task -    ERROR -      start() - Host 'cisco-sw1': task 'send_command' failed with traceback:
Traceback (most recent call last):
  File "/opt/Training/python/automation_training/structured_data/venv/lib/python3.8/site-packages/nornir/core/task.py", line 99, in start
    r = self.task(self, **self.params)
  File "/opt/Training/python/automation_training/structured_data/venv/lib/python3.8/site-packages/nornir_scrapli/tasks/core/send_command.py", line 36, in send_command
    scrapli_conn = task.host.get_connection("scrapli", task.nornir.config)
  File "/opt/Training/python/automation_training/structured_data/venv/lib/python3.8/site-packages/nornir/core/inventory.py", line 494, in get_connection
    self.open_connection(
  File "/opt/Training/python/automation_training/structured_data/venv/lib/python3.8/site-packages/nornir/core/inventory.py", line 546, in open_connection
    conn_obj.open(
  File "/opt/Training/python/automation_training/structured_data/venv/lib/python3.8/site-packages/nornir_scrapli/connection.py", line 105, in open
    connection.open()
  File "/opt/Training/python/automation_training/structured_data/venv/lib/python3.8/site-packages/scrapli/driver/base/sync_driver.py", line 88, in open
    self.channel.channel_authenticate_ssh(
  File "/opt/Training/python/automation_training/structured_data/venv/lib/python3.8/site-packages/scrapli/decorators.py", line 216, in decorate
    return _multiprocessing_timeout(
  File "/opt/Training/python/automation_training/structured_data/venv/lib/python3.8/site-packages/scrapli/decorators.py", line 108, in _multiprocessing_timeout
    return _handle_timeout(
  File "/opt/Training/python/automation_training/structured_data/venv/lib/python3.8/site-packages/scrapli/decorators.py", line 134, in _handle_timeout
    raise ScrapliTimeout(message)
scrapli.exceptions.ScrapliTimeout: timed out during in channel ssh authentication

2022-10-21 15:18:54,809 - nornir.core.task -    ERROR -      start() - Host 'cisco-sw1': task 'pull_structured_data' failed with traceback:
Traceback (most recent call last):
  File "/opt/Training/python/automation_training/structured_data/venv/lib/python3.8/site-packages/nornir/core/task.py", line 99, in start
    r = self.task(self, **self.params)
  File "script1.py", line 9, in pull_structured_data
    version_result = task.run(task=send_command, command="show version")
  File "/opt/Training/python/automation_training/structured_data/venv/lib/python3.8/site-packages/nornir/core/task.py", line 174, in run
    raise NornirSubTaskError(task=run_task, result=r)
nornir.core.exceptions.NornirSubTaskError: Subtask: send_command (failed)


2022-10-24 15:19:14,728 -  nornir.core -     INFO -        run() - Running task 'pull_structured_data' with args {} on 1 hosts
2022-10-24 15:19:17,426 - nornir.core.task -    ERROR -      start() - Host 'cart-colo': task 'send_command' failed with traceback:
Traceback (most recent call last):
  File "/opt/Training/python/automation_training/structured_data/venv/lib/python3.8/site-packages/nornir/core/task.py", line 99, in start
    r = self.task(self, **self.params)
  File "/opt/Training/python/automation_training/structured_data/venv/lib/python3.8/site-packages/nornir_scrapli/tasks/core/send_command.py", line 36, in send_command
    scrapli_conn = task.host.get_connection("scrapli", task.nornir.config)
  File "/opt/Training/python/automation_training/structured_data/venv/lib/python3.8/site-packages/nornir/core/inventory.py", line 494, in get_connection
    self.open_connection(
  File "/opt/Training/python/automation_training/structured_data/venv/lib/python3.8/site-packages/nornir/core/inventory.py", line 546, in open_connection
    conn_obj.open(
  File "/opt/Training/python/automation_training/structured_data/venv/lib/python3.8/site-packages/nornir_scrapli/connection.py", line 105, in open
    connection.open()
  File "/opt/Training/python/automation_training/structured_data/venv/lib/python3.8/site-packages/scrapli/driver/base/sync_driver.py", line 88, in open
    self.channel.channel_authenticate_ssh(
  File "/opt/Training/python/automation_training/structured_data/venv/lib/python3.8/site-packages/scrapli/decorators.py", line 216, in decorate
    return _multiprocessing_timeout(
  File "/opt/Training/python/automation_training/structured_data/venv/lib/python3.8/site-packages/scrapli/decorators.py", line 113, in _multiprocessing_timeout
    return future.result()
  File "/usr/lib/python3.8/concurrent/futures/_base.py", line 437, in result
    return self.__get_result()
  File "/usr/lib/python3.8/concurrent/futures/_base.py", line 389, in __get_result
    raise self._exception
  File "/usr/lib/python3.8/concurrent/futures/thread.py", line 57, in run
    result = self.fn(*self.args, **self.kwargs)
  File "/opt/Training/python/automation_training/structured_data/venv/lib/python3.8/site-packages/scrapli/channel/sync_channel.py", line 290, in channel_authenticate_ssh
    self._ssh_message_handler(output=authenticate_buf)
  File "/opt/Training/python/automation_training/structured_data/venv/lib/python3.8/site-packages/scrapli/channel/base_channel.py", line 432, in _ssh_message_handler
    raise ScrapliAuthenticationFailed(msg)
scrapli.exceptions.ScrapliAuthenticationFailed: No route to host

2022-10-24 15:19:17,426 - nornir.core.task -    ERROR -      start() - Host 'cart-colo': task 'pull_structured_data' failed with traceback:
Traceback (most recent call last):
  File "/opt/Training/python/automation_training/structured_data/venv/lib/python3.8/site-packages/nornir/core/task.py", line 99, in start
    r = self.task(self, **self.params)
  File "script1.py", line 9, in pull_structured_data
    version_result = task.run(task=send_command, command="show version")
  File "/opt/Training/python/automation_training/structured_data/venv/lib/python3.8/site-packages/nornir/core/task.py", line 174, in run
    raise NornirSubTaskError(task=run_task, result=r)
nornir.core.exceptions.NornirSubTaskError: Subtask: send_command (failed)


2022-10-24 15:20:29,916 -  nornir.core -     INFO -        run() - Running task 'pull_structured_data' with args {} on 1 hosts
2022-10-24 15:20:31,417 - nornir.core.task -    ERROR -      start() - Host 'cart-colo': task 'send_command' failed with traceback:
Traceback (most recent call last):
  File "/opt/Training/python/automation_training/structured_data/venv/lib/python3.8/site-packages/nornir/core/task.py", line 99, in start
    r = self.task(self, **self.params)
  File "/opt/Training/python/automation_training/structured_data/venv/lib/python3.8/site-packages/nornir_scrapli/tasks/core/send_command.py", line 36, in send_command
    scrapli_conn = task.host.get_connection("scrapli", task.nornir.config)
  File "/opt/Training/python/automation_training/structured_data/venv/lib/python3.8/site-packages/nornir/core/inventory.py", line 494, in get_connection
    self.open_connection(
  File "/opt/Training/python/automation_training/structured_data/venv/lib/python3.8/site-packages/nornir/core/inventory.py", line 546, in open_connection
    conn_obj.open(
  File "/opt/Training/python/automation_training/structured_data/venv/lib/python3.8/site-packages/nornir_scrapli/connection.py", line 105, in open
    connection.open()
  File "/opt/Training/python/automation_training/structured_data/venv/lib/python3.8/site-packages/scrapli/driver/base/sync_driver.py", line 88, in open
    self.channel.channel_authenticate_ssh(
  File "/opt/Training/python/automation_training/structured_data/venv/lib/python3.8/site-packages/scrapli/decorators.py", line 216, in decorate
    return _multiprocessing_timeout(
  File "/opt/Training/python/automation_training/structured_data/venv/lib/python3.8/site-packages/scrapli/decorators.py", line 113, in _multiprocessing_timeout
    return future.result()
  File "/usr/lib/python3.8/concurrent/futures/_base.py", line 437, in result
    return self.__get_result()
  File "/usr/lib/python3.8/concurrent/futures/_base.py", line 389, in __get_result
    raise self._exception
  File "/usr/lib/python3.8/concurrent/futures/thread.py", line 57, in run
    result = self.fn(*self.args, **self.kwargs)
  File "/opt/Training/python/automation_training/structured_data/venv/lib/python3.8/site-packages/scrapli/channel/sync_channel.py", line 290, in channel_authenticate_ssh
    self._ssh_message_handler(output=authenticate_buf)
  File "/opt/Training/python/automation_training/structured_data/venv/lib/python3.8/site-packages/scrapli/channel/base_channel.py", line 432, in _ssh_message_handler
    raise ScrapliAuthenticationFailed(msg)
scrapli.exceptions.ScrapliAuthenticationFailed: No route to host

2022-10-24 15:20:31,418 - nornir.core.task -    ERROR -      start() - Host 'cart-colo': task 'pull_structured_data' failed with traceback:
Traceback (most recent call last):
  File "/opt/Training/python/automation_training/structured_data/venv/lib/python3.8/site-packages/nornir/core/task.py", line 99, in start
    r = self.task(self, **self.params)
  File "script1.py", line 9, in pull_structured_data
    version_result = task.run(task=send_command, command="show version")
  File "/opt/Training/python/automation_training/structured_data/venv/lib/python3.8/site-packages/nornir/core/task.py", line 174, in run
    raise NornirSubTaskError(task=run_task, result=r)
nornir.core.exceptions.NornirSubTaskError: Subtask: send_command (failed)


2022-10-24 15:20:49,162 -  nornir.core -     INFO -        run() - Running task 'pull_structured_data' with args {} on 1 hosts
2022-10-24 15:20:51,909 - nornir.core.task -    ERROR -      start() - Host 'cart-colo': task 'send_command' failed with traceback:
Traceback (most recent call last):
  File "/opt/Training/python/automation_training/structured_data/venv/lib/python3.8/site-packages/nornir/core/task.py", line 99, in start
    r = self.task(self, **self.params)
  File "/opt/Training/python/automation_training/structured_data/venv/lib/python3.8/site-packages/nornir_scrapli/tasks/core/send_command.py", line 36, in send_command
    scrapli_conn = task.host.get_connection("scrapli", task.nornir.config)
  File "/opt/Training/python/automation_training/structured_data/venv/lib/python3.8/site-packages/nornir/core/inventory.py", line 494, in get_connection
    self.open_connection(
  File "/opt/Training/python/automation_training/structured_data/venv/lib/python3.8/site-packages/nornir/core/inventory.py", line 546, in open_connection
    conn_obj.open(
  File "/opt/Training/python/automation_training/structured_data/venv/lib/python3.8/site-packages/nornir_scrapli/connection.py", line 105, in open
    connection.open()
  File "/opt/Training/python/automation_training/structured_data/venv/lib/python3.8/site-packages/scrapli/driver/base/sync_driver.py", line 88, in open
    self.channel.channel_authenticate_ssh(
  File "/opt/Training/python/automation_training/structured_data/venv/lib/python3.8/site-packages/scrapli/decorators.py", line 216, in decorate
    return _multiprocessing_timeout(
  File "/opt/Training/python/automation_training/structured_data/venv/lib/python3.8/site-packages/scrapli/decorators.py", line 113, in _multiprocessing_timeout
    return future.result()
  File "/usr/lib/python3.8/concurrent/futures/_base.py", line 437, in result
    return self.__get_result()
  File "/usr/lib/python3.8/concurrent/futures/_base.py", line 389, in __get_result
    raise self._exception
  File "/usr/lib/python3.8/concurrent/futures/thread.py", line 57, in run
    result = self.fn(*self.args, **self.kwargs)
  File "/opt/Training/python/automation_training/structured_data/venv/lib/python3.8/site-packages/scrapli/channel/sync_channel.py", line 290, in channel_authenticate_ssh
    self._ssh_message_handler(output=authenticate_buf)
  File "/opt/Training/python/automation_training/structured_data/venv/lib/python3.8/site-packages/scrapli/channel/base_channel.py", line 432, in _ssh_message_handler
    raise ScrapliAuthenticationFailed(msg)
scrapli.exceptions.ScrapliAuthenticationFailed: No route to host

2022-10-24 15:20:51,909 - nornir.core.task -    ERROR -      start() - Host 'cart-colo': task 'pull_structured_data' failed with traceback:
Traceback (most recent call last):
  File "/opt/Training/python/automation_training/structured_data/venv/lib/python3.8/site-packages/nornir/core/task.py", line 99, in start
    r = self.task(self, **self.params)
  File "script1.py", line 9, in pull_structured_data
    version_result = task.run(task=send_command, command="show version")
  File "/opt/Training/python/automation_training/structured_data/venv/lib/python3.8/site-packages/nornir/core/task.py", line 174, in run
    raise NornirSubTaskError(task=run_task, result=r)
nornir.core.exceptions.NornirSubTaskError: Subtask: send_command (failed)


2022-10-24 16:17:30,300 -  nornir.core -     INFO -        run() - Running task 'pull_structured_data' with args {} on 1 hosts
2022-10-24 16:17:30,905 - nornir.core.task -    ERROR -      start() - Host 'cart-colo': task 'send_command' failed with traceback:
Traceback (most recent call last):
  File "/opt/Training/python/automation_training/structured_data/venv/lib/python3.8/site-packages/nornir/core/task.py", line 99, in start
    r = self.task(self, **self.params)
  File "/opt/Training/python/automation_training/structured_data/venv/lib/python3.8/site-packages/nornir_scrapli/tasks/core/send_command.py", line 36, in send_command
    scrapli_conn = task.host.get_connection("scrapli", task.nornir.config)
  File "/opt/Training/python/automation_training/structured_data/venv/lib/python3.8/site-packages/nornir/core/inventory.py", line 494, in get_connection
    self.open_connection(
  File "/opt/Training/python/automation_training/structured_data/venv/lib/python3.8/site-packages/nornir/core/inventory.py", line 546, in open_connection
    conn_obj.open(
  File "/opt/Training/python/automation_training/structured_data/venv/lib/python3.8/site-packages/nornir_scrapli/connection.py", line 105, in open
    connection.open()
  File "/opt/Training/python/automation_training/structured_data/venv/lib/python3.8/site-packages/scrapli/driver/base/sync_driver.py", line 88, in open
    self.channel.channel_authenticate_ssh(
  File "/opt/Training/python/automation_training/structured_data/venv/lib/python3.8/site-packages/scrapli/decorators.py", line 216, in decorate
    return _multiprocessing_timeout(
  File "/opt/Training/python/automation_training/structured_data/venv/lib/python3.8/site-packages/scrapli/decorators.py", line 113, in _multiprocessing_timeout
    return future.result()
  File "/usr/lib/python3.8/concurrent/futures/_base.py", line 437, in result
    return self.__get_result()
  File "/usr/lib/python3.8/concurrent/futures/_base.py", line 389, in __get_result
    raise self._exception
  File "/usr/lib/python3.8/concurrent/futures/thread.py", line 57, in run
    result = self.fn(*self.args, **self.kwargs)
  File "/opt/Training/python/automation_training/structured_data/venv/lib/python3.8/site-packages/scrapli/channel/sync_channel.py", line 302, in channel_authenticate_ssh
    raise ScrapliAuthenticationFailed(msg)
scrapli.exceptions.ScrapliAuthenticationFailed: password prompt seen more than once, assuming auth failed

2022-10-24 16:17:30,906 - nornir.core.task -    ERROR -      start() - Host 'cart-colo': task 'pull_structured_data' failed with traceback:
Traceback (most recent call last):
  File "/opt/Training/python/automation_training/structured_data/venv/lib/python3.8/site-packages/nornir/core/task.py", line 99, in start
    r = self.task(self, **self.params)
  File "script1.py", line 9, in pull_structured_data
    version_result = task.run(task=send_command, command="show version")
  File "/opt/Training/python/automation_training/structured_data/venv/lib/python3.8/site-packages/nornir/core/task.py", line 174, in run
    raise NornirSubTaskError(task=run_task, result=r)
nornir.core.exceptions.NornirSubTaskError: Subtask: send_command (failed)


2022-10-24 16:18:07,588 -  nornir.core -     INFO -        run() - Running task 'pull_structured_data' with args {} on 1 hosts
2022-10-24 16:24:58,745 -  nornir.core -     INFO -        run() - Running task 'pull_structured_data' with args {} on 1 hosts
2022-10-24 16:25:28,102 -  nornir.core -     INFO -        run() - Running task 'pull_structured_data' with args {} on 1 hosts
2022-10-24 16:25:56,000 -  nornir.core -     INFO -        run() - Running task 'pull_structured_data' with args {} on 1 hosts
2022-10-24 16:27:22,147 -  nornir.core -     INFO -        run() - Running task 'pull_structured_data' with args {} on 1 hosts
2022-10-24 16:27:22,154 - nornir.core.task -    ERROR -      start() - Host 'cart-colo': task 'send_command' failed with traceback:
Traceback (most recent call last):
  File "/opt/Training/python/automation_training/structured_data/venv/lib/python3.8/site-packages/scrapli/driver/base/base_driver.py", line 518, in _load_core_transport_plugin
    transport_plugin_module = importlib.import_module(
  File "/usr/lib/python3.8/importlib/__init__.py", line 127, in import_module
    return _bootstrap._gcd_import(name[level:], package, level)
  File "<frozen importlib._bootstrap>", line 1014, in _gcd_import
  File "<frozen importlib._bootstrap>", line 991, in _find_and_load
  File "<frozen importlib._bootstrap>", line 975, in _find_and_load_unlocked
  File "<frozen importlib._bootstrap>", line 671, in _load_unlocked
  File "<frozen importlib._bootstrap_external>", line 848, in exec_module
  File "<frozen importlib._bootstrap>", line 219, in _call_with_frames_removed
  File "/opt/Training/python/automation_training/structured_data/venv/lib/python3.8/site-packages/scrapli/transport/plugins/ssh2/transport.py", line 6, in <module>
    from ssh2.channel import Channel
ModuleNotFoundError: No module named 'ssh2'

The above exception was the direct cause of the following exception:

Traceback (most recent call last):
  File "/opt/Training/python/automation_training/structured_data/venv/lib/python3.8/site-packages/nornir/core/task.py", line 99, in start
    r = self.task(self, **self.params)
  File "/opt/Training/python/automation_training/structured_data/venv/lib/python3.8/site-packages/nornir_scrapli/tasks/core/send_command.py", line 36, in send_command
    scrapli_conn = task.host.get_connection("scrapli", task.nornir.config)
  File "/opt/Training/python/automation_training/structured_data/venv/lib/python3.8/site-packages/nornir/core/inventory.py", line 494, in get_connection
    self.open_connection(
  File "/opt/Training/python/automation_training/structured_data/venv/lib/python3.8/site-packages/nornir/core/inventory.py", line 546, in open_connection
    conn_obj.open(
  File "/opt/Training/python/automation_training/structured_data/venv/lib/python3.8/site-packages/nornir_scrapli/connection.py", line 98, in open
    connection = Scrapli(**parameters, platform=final_platform)
  File "/opt/Training/python/automation_training/structured_data/venv/lib/python3.8/site-packages/scrapli/factory.py", line 506, in __new__
    final_conn = final_driver(**final_kwargs)
  File "/opt/Training/python/automation_training/structured_data/venv/lib/python3.8/site-packages/scrapli/driver/core/arista_eos/sync_driver.py", line 130, in __init__
    super().__init__(
  File "/opt/Training/python/automation_training/structured_data/venv/lib/python3.8/site-packages/scrapli/driver/network/sync_driver.py", line 48, in __init__
    super().__init__(
  File "/opt/Training/python/automation_training/structured_data/venv/lib/python3.8/site-packages/scrapli/driver/generic/sync_driver.py", line 47, in __init__
    super().__init__(
  File "/opt/Training/python/automation_training/structured_data/venv/lib/python3.8/site-packages/scrapli/driver/base/sync_driver.py", line 15, in __init__
    super().__init__(**kwargs)
  File "/opt/Training/python/automation_training/structured_data/venv/lib/python3.8/site-packages/scrapli/driver/base/base_driver.py", line 185, in __init__
    transport_class, self._plugin_transport_args = self._transport_factory()
  File "/opt/Training/python/automation_training/structured_data/venv/lib/python3.8/site-packages/scrapli/driver/base/base_driver.py", line 460, in _transport_factory
    transport_class, _plugin_transport_args_class = self._load_core_transport_plugin()
  File "/opt/Training/python/automation_training/structured_data/venv/lib/python3.8/site-packages/scrapli/driver/base/base_driver.py", line 531, in _load_core_transport_plugin
    raise ScrapliTransportPluginError(exception_message) from exc
scrapli.exceptions.ScrapliTransportPluginError: 

************************************************************************************************************************************* Transport Plugin Extra Not Installed! *************************************************************************************************************************************
                                          Optional transport plugin 'ssh2' is not installed!
To resolve this issue, install the transport plugin. You can do this in one of the following ways:
1: 'pip install -r requirements-ssh2.txt'
2: 'pip install scrapli[ssh2]'                                         
*****************************************************************************************************************************************************************************************************************************************************************************************************************


2022-10-24 16:27:22,154 - nornir.core.task -    ERROR -      start() - Host 'cart-colo': task 'pull_structured_data' failed with traceback:
Traceback (most recent call last):
  File "/opt/Training/python/automation_training/structured_data/venv/lib/python3.8/site-packages/nornir/core/task.py", line 99, in start
    r = self.task(self, **self.params)
  File "script1.py", line 11, in pull_structured_data
    version_result = task.run(task=send_command, command="show ip int br")
  File "/opt/Training/python/automation_training/structured_data/venv/lib/python3.8/site-packages/nornir/core/task.py", line 174, in run
    raise NornirSubTaskError(task=run_task, result=r)
nornir.core.exceptions.NornirSubTaskError: Subtask: send_command (failed)


2022-10-24 16:28:04,055 -  nornir.core -     INFO -        run() - Running task 'pull_structured_data' with args {} on 1 hosts
2022-10-24 16:44:21,227 -  nornir.core -     INFO -        run() - Running task 'pull_structured_data' with args {} on 1 hosts
2022-10-24 16:48:58,686 -  nornir.core -     INFO -        run() - Running task 'pull_structured_data' with args {} on 1 hosts
2022-10-24 16:49:56,380 -  nornir.core -     INFO -        run() - Running task 'pull_structured_data' with args {} on 1 hosts
2022-10-24 16:51:04,702 -  nornir.core -     INFO -        run() - Running task 'pull_structured_data' with args {} on 2 hosts
2022-10-24 16:54:45,671 -  nornir.core -     INFO -        run() - Running task 'pull_structured_data' with args {} on 2 hosts
2022-10-24 16:54:47,533 - nornir.core.task -    ERROR -      start() - Host 'cart-colo': task 'pull_structured_data' failed with traceback:
Traceback (most recent call last):
  File "/opt/Training/python/automation_training/structured_data/venv/lib/python3.8/site-packages/nornir/core/task.py", line 99, in start
    r = self.task(self, **self.params)
  File "script1.py", line 13, in pull_structured_data
    print_structured_result(task.host["facts"])
  File "/opt/Training/python/automation_training/structured_data/venv/lib/python3.8/site-packages/nornir_scrapli/functions/print_structured_result.py", line 35, in print_structured_result
    updated_agg_result = AggregatedResult(result.name)
AttributeError: 'list' object has no attribute 'name'

2022-10-24 16:54:48,594 - nornir.core.task -    ERROR -      start() - Host 'cisco-sw1': task 'pull_structured_data' failed with traceback:
Traceback (most recent call last):
  File "/opt/Training/python/automation_training/structured_data/venv/lib/python3.8/site-packages/nornir/core/task.py", line 99, in start
    r = self.task(self, **self.params)
  File "script1.py", line 13, in pull_structured_data
    print_structured_result(task.host["facts"])
  File "/opt/Training/python/automation_training/structured_data/venv/lib/python3.8/site-packages/nornir_scrapli/functions/print_structured_result.py", line 35, in print_structured_result
    updated_agg_result = AggregatedResult(result.name)
AttributeError: 'list' object has no attribute 'name'

2022-10-24 16:55:26,289 -  nornir.core -     INFO -        run() - Running task 'pull_structured_data' with args {} on 2 hosts
2022-10-24 16:56:03,209 -  nornir.core -     INFO -        run() - Running task 'pull_structured_data' with args {} on 7 hosts
2022-10-24 16:58:01,542 -  nornir.core -     INFO -        run() - Running task 'pull_structured_data' with args {} on 7 hosts
2022-10-24 16:58:17,192 -  nornir.core -     INFO -        run() - Running task 'pull_structured_data' with args {} on 7 hosts
2022-10-24 16:58:53,801 -  nornir.core -     INFO -        run() - Running task 'pull_structured_data' with args {} on 7 hosts
2022-10-24 16:59:20,190 -  nornir.core -     INFO -        run() - Running task 'pull_structured_data' with args {} on 7 hosts
2022-10-24 16:59:32,409 -  nornir.core -     INFO -        run() - Running task 'pull_structured_data' with args {} on 7 hosts
2022-10-24 16:59:48,322 -  nornir.core -     INFO -        run() - Running task 'pull_structured_data' with args {} on 7 hosts
2022-10-24 16:59:49,429 - nornir.core.task -    ERROR -      start() - Host 'ny5-feed-sw1a': task 'pull_structured_data' failed with traceback:
Traceback (most recent call last):
  File "/opt/Training/python/automation_training/structured_data/venv/lib/python3.8/site-packages/nornir/core/task.py", line 99, in start
    r = self.task(self, **self.params)
  File "script1.py", line 11, in pull_structured_data
    task.run(task=send_command, command="show ntp ")
  File "/opt/Training/python/automation_training/structured_data/venv/lib/python3.8/site-packages/nornir/core/task.py", line 174, in run
    raise NornirSubTaskError(task=run_task, result=r)
nornir.core.exceptions.NornirSubTaskError: Subtask: send_command (failed)


2022-10-24 16:59:49,456 - nornir.core.task -    ERROR -      start() - Host 'telx-colo': task 'pull_structured_data' failed with traceback:
Traceback (most recent call last):
  File "/opt/Training/python/automation_training/structured_data/venv/lib/python3.8/site-packages/nornir/core/task.py", line 99, in start
    r = self.task(self, **self.params)
  File "script1.py", line 11, in pull_structured_data
    task.run(task=send_command, command="show ntp ")
  File "/opt/Training/python/automation_training/structured_data/venv/lib/python3.8/site-packages/nornir/core/task.py", line 174, in run
    raise NornirSubTaskError(task=run_task, result=r)
nornir.core.exceptions.NornirSubTaskError: Subtask: send_command (failed)


2022-10-24 16:59:49,464 - nornir.core.task -    ERROR -      start() - Host 'ny5-feed-sw1b': task 'pull_structured_data' failed with traceback:
Traceback (most recent call last):
  File "/opt/Training/python/automation_training/structured_data/venv/lib/python3.8/site-packages/nornir/core/task.py", line 99, in start
    r = self.task(self, **self.params)
  File "script1.py", line 11, in pull_structured_data
    task.run(task=send_command, command="show ntp ")
  File "/opt/Training/python/automation_training/structured_data/venv/lib/python3.8/site-packages/nornir/core/task.py", line 174, in run
    raise NornirSubTaskError(task=run_task, result=r)
nornir.core.exceptions.NornirSubTaskError: Subtask: send_command (failed)


2022-10-24 16:59:49,465 - nornir.core.task -    ERROR -      start() - Host 'ny5-feed-sw3': task 'pull_structured_data' failed with traceback:
Traceback (most recent call last):
  File "/opt/Training/python/automation_training/structured_data/venv/lib/python3.8/site-packages/nornir/core/task.py", line 99, in start
    r = self.task(self, **self.params)
  File "script1.py", line 11, in pull_structured_data
    task.run(task=send_command, command="show ntp ")
  File "/opt/Training/python/automation_training/structured_data/venv/lib/python3.8/site-packages/nornir/core/task.py", line 174, in run
    raise NornirSubTaskError(task=run_task, result=r)
nornir.core.exceptions.NornirSubTaskError: Subtask: send_command (failed)


2022-10-24 16:59:49,466 - nornir.core.task -    ERROR -      start() - Host 'cart-colo': task 'pull_structured_data' failed with traceback:
Traceback (most recent call last):
  File "/opt/Training/python/automation_training/structured_data/venv/lib/python3.8/site-packages/nornir/core/task.py", line 99, in start
    r = self.task(self, **self.params)
  File "script1.py", line 11, in pull_structured_data
    task.run(task=send_command, command="show ntp ")
  File "/opt/Training/python/automation_training/structured_data/venv/lib/python3.8/site-packages/nornir/core/task.py", line 174, in run
    raise NornirSubTaskError(task=run_task, result=r)
nornir.core.exceptions.NornirSubTaskError: Subtask: send_command (failed)


2022-10-24 16:59:49,508 - nornir.core.task -    ERROR -      start() - Host 'ny5-feed-sw2': task 'pull_structured_data' failed with traceback:
Traceback (most recent call last):
  File "/opt/Training/python/automation_training/structured_data/venv/lib/python3.8/site-packages/nornir/core/task.py", line 99, in start
    r = self.task(self, **self.params)
  File "script1.py", line 11, in pull_structured_data
    task.run(task=send_command, command="show ntp ")
  File "/opt/Training/python/automation_training/structured_data/venv/lib/python3.8/site-packages/nornir/core/task.py", line 174, in run
    raise NornirSubTaskError(task=run_task, result=r)
nornir.core.exceptions.NornirSubTaskError: Subtask: send_command (failed)


2022-10-24 16:59:51,404 - nornir.core.task -    ERROR -      start() - Host 'cisco-sw1': task 'pull_structured_data' failed with traceback:
Traceback (most recent call last):
  File "/opt/Training/python/automation_training/structured_data/venv/lib/python3.8/site-packages/nornir/core/task.py", line 99, in start
    r = self.task(self, **self.params)
  File "script1.py", line 11, in pull_structured_data
    task.run(task=send_command, command="show ntp ")
  File "/opt/Training/python/automation_training/structured_data/venv/lib/python3.8/site-packages/nornir/core/task.py", line 174, in run
    raise NornirSubTaskError(task=run_task, result=r)
nornir.core.exceptions.NornirSubTaskError: Subtask: send_command (failed)


2022-10-24 17:01:43,948 -  nornir.core -     INFO -        run() - Running task 'pull_structured_data' with args {} on 7 hosts
